Workbook

Sheet Apuração
B3: Apuração PIS/COFINS - SAP
B4: SOMPO SERVICES
D5: 01.2026 | E5: 02.2026 | F5: 03.2026 | G5: 04.2026 | H5: 05.2026 | I5: 06.2026 | J5: 07.2026 | K5: 08.2026 | L5: 09.2026 | M5: 10.2026 | N5: 11.2026 | O5: 12.2026 | Q5: 05.2026
C6: RECEITAS - PRESTAÇÃO DE SERVIÇO
B7: 35199998 | C7: RECEITAS PREST SERV | D7: =IFERROR(VLOOKUP(B7,'Bal 012026'!B:H,6,0),0) -> -7990.17 | E7: =IFERROR(VLOOKUP(B7,'Bal 022026'!$B:$H,6,0),0) -> -3906.58 | F7: =IFERROR(VLOOKUP($B$7,'Bal 032026'!$B:$H,6,0),0) -> -4605.8 | G7: =IFERROR(VLOOKUP(B7,'Bal 042026'!B:H,6,0),0) -> -2559.73 | H7: =IFERROR(VLOOKUP(B7,'Bal 052026'!B:H,6,0),0) -> -6624.52 | I7: =IFERROR(VLOOKUP(B7,'Bal 06.2026'!B:H,6,0),0) -> -7391.75 | J7: =IFERROR(VLOOKUP(B7,'Bal 07.2026'!A:G,6,0),0) -> 0 | K7: =IFERROR(VLOOKUP(B7,'Bal 08.2026'!A:G,6,0),0) -> 0 | L7: =VLOOKUP(B7,'Bal 09.2026'!A:G,6,0) -> #N/A | M7: =VLOOKUP(B7,'Bal 10.2026'!A:G,6,0) -> #N/A | N7: =IFERROR(VLOOKUP(B7,'Bal 11.2026'!A:G,6,0),0) -> 0 | O7: =IFERROR(VLOOKUP(B7,'Bal 12.2026'!A:G,6,0),0) -> 0 | Q7: 0
B8: 35199995 | C8: Receita SompoRisk | D8: =IFERROR(VLOOKUP(B8,'Bal 012026'!B:H,6,0),0) -> -37147.5 | E8: =IFERROR(VLOOKUP(B8,'Bal 022026'!$B:$H,6,0),0) -> -40552 | F8: =IFERROR(VLOOKUP($B$8,'Bal 032026'!$B:$H,6,0),0) -> -33550 | G8: =IFERROR(VLOOKUP(B8,'Bal 042026'!B:H,6,0),0) -> -55209.5 | H8: =IFERROR(VLOOKUP(B8,'Bal 052026'!B:H,6,0),0) -> -85622.5 | I8: =IFERROR(VLOOKUP(B8,'Bal 06.2026'!B:H,6,0),0) -> -79219 | O8: =IFERROR(VLOOKUP(B8,'Bal 12.2026'!A:G,6,0),0) -> 0 | P8: A100 | Q8: -85622.5
C9: TOTAL RECEITAS PRESTAÇÃO DE SERVIÇO | D9: =SUM(D7:D8) -> -45137.67 | E9: =SUM(E7:E8) -> -44458.58 | F9: =SUM(F7:F8) -> -38155.8 | G9: =SUM(G7:G8) -> -57769.23 | H9: =SUM(H7:H8) -> -92247.02 | I9: =SUM(I7:I8) -> -86610.75 | J9: =SUM(J7:J7) -> 0 | K9: =SUM(K7:K7) -> 0 | L9: =SUM(L7:L7) -> #N/A | M9: =SUM(M7:M7) -> #N/A | N9: =SUM(N7:N7) -> 0 | O9: =SUM(O7:O8) -> 0 | Q9: -85622.5
B10: 0.0165 | C10: PIS SOBRE RECEITA (1,65%) | D10: =D9*B10 -> -744.77156 | E10: =E9*1.65% -> -733.56657 | F10: =F9*1.65% -> -629.5707 | G10: =G9*1.65% -> -953.1923 | H10: =H9*1.65% -> -1522.0758 | I10: =I9*1.65% -> -1429.0774 | J10: =J9*1.65% -> 0 | K10: =K9*1.65% -> 0 | L10: =L9*1.65% -> #N/A | ... O10: =O9*1.65% -> 0 | Q10: -1412.7713
B11: 0.076 | C11: COFINS SOBRE RECEITA (7,60%) | D11: =D9*B11 -> -3430.4629 | E11: =E9*B11 -> -3378.8521 | F11: =F9*7.6% -> -2899.8408 | G11: =G9*7.6% -> -4390.4615 | H11: =H9*7.6% -> -7010.7735 | I11: =I9*7.6% -> -6582.417 | J11: =J9*7.6% -> 0 | K11: =K9*7.6% -> 0 | L11: =L9*7.6% -> #N/A | M11: =M9*7.6% -> #N/A | ... O11: =O9*7.6% -> 0 | Q11: -6507.31
C13: RECEITAS FINANCEIRAS
B14: 36114001 | C14: FDO ÑEX VC (DPV)GAIN | D14: =IFERROR(VLOOKUP(B14,'Bal 012026'!B:H,6,0),0) -> -6200.26 | E14: =IFERROR(VLOOKUP($B$14,'Bal 022026'!$B:$H,6,0),0) -> -6152.41 | F14: =IFERROR(VLOOKUP(B14,'Bal 032026'!$B:$H,6,0),0) -> -7276.93 | G14: =IFERROR(VLOOKUP(B14,'Bal 042026'!B:H,6,0),0) -> -6578.34 | H14: =IFERROR(VLOOKUP(B14,'Bal 052026'!B:H,6,0),0) -> -6759.61 | I14: =IFERROR(VLOOKUP(B14,'Bal 06.2026'!B:H,6,0),0) -> -6936.26 | J14: =IFERROR(VLOOKUP(B14,'Bal 07.2026'!A:G,6,0),0) -> 0 | K14: =IFERROR(VLOOKUP(B14,'Bal 08.2026'!A:G,6,0),0) -> 0 | L14: =IFERROR(VLOOKUP(B14,'Bal 09.2026'!A:G,6,0),0) -> 0 | M14: =IFERROR(VLOOKUP(B14,'Bal 10.2026'!A:G,6,0),0) -> 0 | N14: =IFERROR(VLOOKUP(B14,'Bal 11.2026'!A:G,6,0),0) -> 0 | O14: =IFERROR(VLOOKUP(B14,'Bal 12.2026'!A:G,6,0),0) -> 0 | P14: F100 | Q14: 0
B15: 36910001 | C15: JUROS S/CRED.TRIBUT | D15: =IFERROR(VLOOKUP(B15,'Bal 012026'!B:H,6,0),0) -> -8252 | E15: =IFERROR(VLOOKUP($B$15,'Bal 022026'!$B:$H,6,0),0) -> -7113.78 | F15: -8607.69 | G15: =IFERROR(VLOOKUP(B15,'Bal 042026'!B:H,6,0),0) -> -4495.54 | H15: =IFERROR(VLOOKUP(B15,'Bal 052026'!B:H,6,0),0) -> -7611.75 | I15: =IFERROR(VLOOKUP(B15,'Bal 06.2026'!B:H,6,0),0) -> -7967.44 | J15: =IFERROR(VLOOKUP(B15,'Bal 07.2026'!A:G,6,0),0) -> 0 | K15: =IFERROR(VLOOKUP(B15,'Bal 08.2026'!A:G,6,0),0) -> 0 | L15: =IFERROR(VLOOKUP(B15,'Bal 09.2026'!A:G,6,0),0) -> 0 | M15: =IFERROR(VLOOKUP(B15,'Bal 10.2026'!A:G,6,0),0) -> 0 | N15: =IFERROR(VLOOKUP(B15,'Bal 11.2026'!A:G,6,0),0) -> 0 | O15: =IFERROR(VLOOKUP(B15,'Bal 12.2026'!A:G,6,0),0) -> 0 | Q15: 0
B16: 36990099 | C16: OUTRAS REC.FINAN EV | D16: =IFERROR(VLOOKUP(B16,'Bal 012026'!B:H,6,0),0) -> -528.68 | E16: =IFERROR(VLOOKUP($B$16,'Bal 022026'!$B:$H,6,0),0)*0-'Bal 022026'!F148 -> -528.68 | F16: =IFERROR(VLOOKUP(B16,'Bal 032026'!$B:$H,6,0),0) -> -528.68 | G16: =IFERROR(VLOOKUP(B16,'Bal 042026'!B:G,6,0),0) -> -528.68 | H16: =IFERROR(VLOOKUP(B16,'Bal 052026'!B:H,6,0),0) -> -628.24 | I16: =IFERROR(VLOOKUP(B16,'Bal 06.2026'!B:H,6,0),0) -> -1337.18 | J16: =IFERROR(VLOOKUP(B16,'Bal 07.2026'!A:G,6,0),0) -> 0 | K16: =IFERROR(VLOOKUP(B16,'Bal 08.2026'!A:G,6,0),0) -> 0 | L16: =IFERROR(VLOOKUP(B16,'Bal 09.2026'!A:G,6,0),0) -> 0 | M16: =IFERROR(VLOOKUP(B16,'Bal 10.2026'!A:G,6,0),0) -> 0 | N16: =IFERROR(VLOOKUP(B16,'Bal 11.2026'!A:G,6,0),0) -> 0 | O16: =IFERROR(VLOOKUP(B16,'Bal 12.2026'!A:G,6,0),0) -> 0 | Q16: 0
C17: TOTAL RECEITAS FINANCEIRA | D17: =SUM(D14:D16) -> -14980.94 | E17: =SUM(E14:E16) -> -13794.87 | F17: =SUM(F14:F16) -> -16413.3 | G17: =SUM(G14:G16) -> -11602.56 | H17: =SUM(H14:H16) -> -14999.6 | I17: =SUM(I14:I16) -> -16240.88 | J17: =SUM(J14:J16) -> 0 | K17: =SUM(K14:K16) -> 0 | ... O17: =SUM(O14:O16) -> 0 | Q17: 0
B18: 0.0065 | C18: PIS SOBRE RECEITA FINANCEIRA(0,65%) | D18: =D17*B18 -> -97.37611 | E18: =E17*B18 -> -89.666655 | F18: =F17*0.65% -> -106.68645 | G18: =G17*0.65% -> -75.41664 | H18: =H17*0.65% -> -97.4974 | I18: =I17*0.65% -> -105.56572 | J18: =J17*0.65% -> 0 | K18: =K17*0.65% -> 0 | L18: =L17*0.65% -> 0 | M18: =M17*0.65% -> 0 | ... O18: =O17*0.65% -> 0 | Q18: 0
B19: 0.04 | C19: COFINS SOBRE RECEITA FINANCEIRA (4,00%) | D19: =D17*B19 -> -599.2376 | E19: =E17*B19 -> -551.7948 | F19: =F17*4% -> -656.532 | G19: =G17*4% -> -464.1024 | H19: =H17*4% -> -599.984 | I19: =I17*4% -> -649.6352 | J19: =J17*4% -> 0 | K19: =K17*4% -> 0 | L19: =L17*4% -> 0 | M19: =M17*4% -> 0 | ... O19: =O17*4% -> 0 | Q19: 0
B21: 21131602 | C21: PIS | D21: =D10+D18 -> -842.14767 | E21: =E10+E18 -> -823.23323 | F21: =F10+F18 -> -736.25715 | G21: =G10+G18 -> -1028.6089 | H21: =H10+H18 -> -1619.5732 | I21: =I10+I18 -> -1534.6431 | J21: =J10+J18 -> 0 | K21: =K10+K18 -> 0 | ... O21: =O10+O18 -> 0 | Q21: -1412.7713
B22: 21131601 | C22: COFINS | D22: =D11+D19 -> -4029.7005 | E22: =E11+E19 -> -3930.6469 | F22: =F11+F19 -> -3556.3728 | G22: =G11+G19 -> -4854.5639 | H22: =H11+H19 -> -7610.7575 | I22: =I11+I19 -> -7232.0522 | J22: =J11+J19 -> 0 | K22: =K11+K19 -> 0 | ... O22: =O11+O19 -> 0 | Q22: -6507.31
B24: 11644004 | C24: RETIDOS do Mes PIS | D24: 296.5 | E24: 154.13 | N24: 0
B25: 11644005 | C25: RETIDOS do Mês COFINS | D25: 1368.48 | E25: 848.69 | N25: 0
C27: Compensação Saldo Residual PIS | D27: 545.65 | E27: 669.1 | F27: 736.26 | G27: 0 | H27: 0 | Q27: 0
C28: Compensação Saldo Residual COFINS | D28: 2661.22 | E28: 3081.96 | F28: 3556.37 | G28: 0 | H28: 0 | Q28: 0
B30: 6912 | C30: PIS A RECOLHER | D30: =D21+D24+D27 -> 0.002335 | E30: =E21+E24+E27 -> -0.003225 | F30: =F21+F24+F27 -> 0.00285 | G30: =G21+G24+G27 -> -1028.6089 | H30: =H21+H24+H27 -> -1619.5732 | I30: =I21+I24+I27 -> -1534.6431 | J30: =J21+J24+J27 -> 0 | K30: =K21+K24+K27 -> 0 | ... O30: =O21+O24+O27 -> 0 | Q30: -1412.7713
C31: DARF
D32: =D30+D31 -> 0.002335 | E32: =E30+E31 -> -0.003225 | F32: =F30+F31 -> 0.00285 | G32: =G30+G31 -> -1028.6089 | H32: =H30+H31 -> -1619.5732 | I32: =I30+I31 -> -1534.6431 | J32: =J30+J31 -> 0 | K32: =K30+K31 -> 0 | ... O32: =O30+O31 -> 0 | Q32: -1412.7713
B34: 5856 | C34: COFINS A RECOLHER | D34: =D22+D25+D28 -> -0.00052 | E34: =E22+E25+E28 -> 0.00312 | F34: =F22+F25+F28 -> -0.0028 | G34: =G22+G25+G28 -> -4854.5639 | H34: =H22+H25+H28 -> -7610.7575 | I34: =I22+I25+I28 -> -7232.0522 | J34: =J22+J25+J28 -> 0 | K34: =K22+K25+K28 -> 0 | ... O34: =O22+O25+O28 -> 0 | Q34: -6507.31
C35: DARF
D36: =D34+D35 -> -0.00052 | E36: =E34+E35 -> 0.00312 | F36: =F34+F35 -> -0.0028 | G36: =G34+G35 -> -4854.5639 | H36: =H34+H35 -> -7610.7575 | I36: =I34+I35 -> -7232.0522 | J36: =J34+J35 -> 0 | K36: =K34+K35 -> 0 | ... O36: =O34+O35 -> 0 | Q36: -6507.31
C38: CONTABILIZAÇÃO
B39: 21131602 | C39: PIS/PASEP A RECOLHER | D39: =IFERROR(VLOOKUP(B39,'Bal 012026'!B:H,7,0),0) -> -842.15 | E39: =IFERROR(VLOOKUP($B$39,'Bal 022026'!$B:$H,7,0),0) -> -154.13 | F39: =IFERROR(VLOOKUP(B39,'Bal 032026'!$B:$H,7,0),0) -> 736.26 | G39: =IFERROR(VLOOKUP(B39,'Bal 042026'!B:H,7,0),0) -> -1028.61 | H39: =IFERROR(VLOOKUP(B39,'Bal 052026'!B:H,7,0),0) -> -1619.57 | I39: =IFERROR(VLOOKUP($B$39,'Bal 06.2026'!B:H,7,0),0) -> 0 | J39: =IFERROR(VLOOKUP(B39,'Bal 07.2026'!A:G,7,0),0) -> 0 | K39: =IFERROR(VLOOKUP(B39,'Bal 08.2026'!A:G,7,0),0) -> 0 | L39: =IFERROR(VLOOKUP(B39,'Bal 09.2026'!A:G,7,0),0) -> 0 | M39: =IFERROR(VLOOKUP(B39,'Bal 10.2026'!A:G,7,0),0) -> 0 | N39: =IFERROR(VLOOKUP(B39,'Bal 11.2026'!A:G,7,0),0) -> 0 | O39: =IFERROR(VLOOKUP(B39,'Bal 12.2026'!A:G,7,0),0) -> 0 | Q39: 0
B40: 21131601 | C40: COFINS A RECOLHER | D40: =IFERROR(VLOOKUP(B40,'Bal 012026'!B:H,7,0),0) -> -4029.7 | E40: =IFERROR(VLOOKUP($B$40,'Bal 022026'!$B:$H,7,0),0) -> -848.69 | F40: =IFERROR(VLOOKUP(B40,'Bal 032026'!$B:$H,7,0),0) -> 3556.37 | G40: =IFERROR(VLOOKUP(B40,'Bal 042026'!B:H,7,0),0) -> -4854.56 | H40: =IFERROR(VLOOKUP(B40,'Bal 052026'!B:H,7,0),0) -> -7610.76 | I40: =IFERROR(VLOOKUP($B$39,'Bal 06.2026'!B:H,7,0),0) -> 0 | J40: =IFERROR(VLOOKUP(B40,'Bal 07.2026'!A:G,7,0),0) -> 0 | K40: =IFERROR(VLOOKUP(B40,'Bal 08.2026'!A:G,7,0),0) -> 0 | L40: =IFERROR(VLOOKUP(B40,'Bal 09.2026'!A:G,7,0),0) -> 0 | M40: =IFERROR(VLOOKUP(B40,'Bal 10.2026'!A:G,7,0),0) -> 0 | N40: =IFERROR(VLOOKUP(B40,'Bal 11.2026'!A:G,7,0),0) -> 0 | O40: =IFERROR(VLOOKUP(B40,'Bal 12.2026'!A:G,7,0),0) -> 0 | Q40: 0
C41: Check | E41: =E21-E39 -> -669.10323 | F41: =F21+F39 -> 0.00285 | G41: =G21-G39 -> 0.001065 | H41: =H21-H39 -> -0.00323
E42: =E22-E40 -> -3081.9569 | F42: =F22+F40 -> -0.0028 | G42: =G22-G40 -> -0.00388 | H42: =H22-H40 -> 0.00248

Sheet Bal 06.2026
B1: Table
C2: Exercício/período | D2: 006.2026 | E2: 006.2026 | F2: 006.2026 | G2: 006.2026 | H2: 006.2026
B3: Conta do Razão | D3: Saldo Anterior | E3: Débitos | F3: Créditos | G3: Movimento | H3: Saldo Acumulado
A4: =IF(LEN(B4)=8,LEFT(B4,1),0) -> 0 | B4: G517 | C4: PLANO DE CONTAS CONS | D4: -0.02 | E4: 682875.25 | F4: 682875.23 | G4: 0.02 | H4: 0
A5: =IF(LEN(B5)=8,LEFT(B5,1),0) -> 0 | B5: G5171 | C5: ATIVO | D5: 2910168.8 | E5: 485093.34 | F5: 441370.95 | G5: 43722.39 | H5: 2953891.1
A6: =IF(LEN(B6)=8,LEFT(B6,1),0) -> 0 | B6: G51711 | C6: CIRCULANTE | D6: 2587946.5 | E6: 484564.66 | F6: 429731.16 | G6: 54833.5 | H6: 2642780
A7: =IF(LEN(B7)=8,LEFT(B7,1),0) -> 0 | B7: G517111 | C7: DISPONÍVEL | D7: 205461.79 | E7: 359433.77 | F7: 314727.93 | G7: 44705.84 | H7: 250167.63
A8: =IF(LEN(B8)=8,LEFT(B8,1),0) -> G | B8: G5171113 | C8: BANCOS CONTA DEPÓSIT | D8: 205461.79 | E8: 359433.77 | F8: 314727.93 | G8: 44705.84 | H8: 250167.63
A9: =IF(LEN(B9)=8,LEFT(B9,1),0) -> 0 | B9: G51711131 | C9: BANCOS CONTA DEPÓSIT | D9: 205461.79 | E9: 359433.77 | F9: 314727.93 | G9: 44705.84 | H9: 250167.63
A10: =IF(LEN(B10)=8,LEFT(B10,1),0) -> 1 | B10: 11131050 | C10: BCO SANTANDER | D10: 71087.8 | E10: 20325.44 | F10: 50552 | G10: -30226.56 | H10: 40861.24
A11: =IF(LEN(B11)=8,LEFT(B11,1),0) -> 1 | B11: 11131090 | C11: BANCO SANTANDER | D11: 118258.02 | E11: 63877.81 | F11: 240.1 | G11: 63637.71 | H11: 181895.73
A12: =IF(LEN(B12)=8,LEFT(B12,1),0) -> 1 | B12: 11131091 | C12: BANCO SANTANDER | D12: 16508.35 | E12: 11100.68 | F12: 198.37 | G12: 10902.31 | H12: 27410.66
A13: =IF(LEN(B13)=8,LEFT(B13,1),0) -> 1 | B13: 11132050 | C13: BCO SANTANDER | D13: 0 | E13: 33942.06 | F13: 33942.06 | G13: 0 | H13: 0
A14: =IF(LEN(B14)=8,LEFT(B14,1),0) -> 1 | B14: 11132090 | C14: BANCO SANTANDER | D14: -392.38 | E14: 107071.42 | F14: 106679.04 | G14: 392.38 | H14: 0
A15: =IF(LEN(B15)=8,LEFT(B15,1),0) -> 1 | B15: 11132091 | C15: BANCO SANTANDER | D15: 0 | E15: 22201.36 | F15: 22201.36 | G15: 0 | H15: 0
A16: =IF(LEN(B16)=8,LEFT(B16,1),0) -> 1 | B16: 11133050 | C16: BCO SANTANDER SAIDA | D16: 0 | E16: 100915 | F16: 100915 | G16: 0 | H16: 0
A17: =IF(LEN(B17)=8,LEFT(B17,1),0) -> 0 | B17: G517112 | C17: APLICAÇÕES | D17: 616021.84 | E17: 6936.26 | F17: 0 | G17: 6936.26 | H17: 622958.1
A18: =IF(LEN(B18)=8,LEFT(B18,1),0) -> G | B18: G5171126 | C18: QUOTAS DE FUNDOS DE | D18: 616021.84 | E18: 6936.26 | F18: 0 | G18: 6936.26 | H18: 622958.1
A19: =IF(LEN(B19)=8,LEFT(B19,1),0) -> 0 | B19: G51711261 | C19: VINCULADAS À COBERTU | D19: 616021.84 | E19: 6936.26 | F19: 0 | G19: 6936.26 | H19: 622958.1
A20: =IF(LEN(B20)=8,LEFT(B20,1),0) -> 0 | B20: G517112612 | C20: QUOTAS DE OUTROS FUN | D20: 616021.84 | E20: 6936.26 | F20: 0 | G20: 6936.26 | H20: 622958.1
A21: =IF(LEN(B21)=8,LEFT(B21,1),0) -> 0 | B21: G5171126121 | C21: VALOR ORIGINAL | D21: 616021.84 | E21: 6936.26 | F21: 0 | G21: 6936.26 | H21: 622958.1
A22: =IF(LEN(B22)=8,LEFT(B22,1),0) -> 1 | B22: 11240001 | C22: FD ÑEX CUV VC CP DPV | D22: 616021.84 | E22: 6936.26 | F22: 0 | G22: 6936.26 | H22: 622958.1
A23: =IF(LEN(B23)=8,LEFT(B23,1),0) -> 0 | B23: G517113 | C23: CRÉDITOS DAS OPERAÇÕ | D23: 41642 | E23: 97558.95 | F23: 96588.65 | G23: 970.3 | H23: 42612.3
A24: =IF(LEN(B24)=8,LEFT(B24,1),0) -> G | B24: G5171131 | C24: PRÊMIOS A RECEBER | D24: 41642 | E24: 96735.3 | F24: 95765 | G24: 970.3 | H24: 42612.3
A25: =IF(LEN(B25)=8,LEFT(B25,1),0) -> 0 | B25: G51711311 | C25: DIRETO | D25: 41642 | E25: 96735.3 | F25: 95765 | G25: 970.3 | H25: 42612.3
A26: =IF(LEN(B26)=8,LEFT(B26,1),0) -> 0 | B26: G517113111 | C26: PRÊMIOS - RISCOS VIG | D26: 41642 | E26: 96735.3 | F26: 95765 | G26: 970.3 | H26: 42612.3
A27: =IF(LEN(B27)=8,LEFT(B27,1),0) -> 1 | B27: 11311011 | C27: SOMPO SEG REC RECEIT | D27: 0 | E27: 17447.3 | F27: 16576 | G27: 871.3 | H27: 871.3
A28: =IF(LEN(B28)=8,LEFT(B28,1),0) -> 1 | B28: 11311094 | C28: Clientes SompoRisk | D28: 41642 | E28: 79288 | F28: 79189 | G28: 99 | H28: 41741
A29: =IF(LEN(B29)=8,LEFT(B29,1),0) -> G | B29: G5171138 | C29: OUTROS CRÉDITOS OPER | D29: 0 | E29: 823.65 | F29: 823.65 | G29: 0 | H29: 0
A30: =IF(LEN(B30)=8,LEFT(B30,1),0) -> 0 | B30: G51711388 | C30: OUTROS CRÉDITOS | D30: 0 | E30: 823.65 | F30: 823.65 | G30: 0 | H30: 0
A31: =IF(LEN(B31)=8,LEFT(B31,1),0) -> 1 | B31: 11391004 | C31: SALVADO VEND RECEBER | D31: 0 | E31: 388 | F31: 388 | G31: 0 | H31: 0
A32: =IF(LEN(B32)=8,LEFT(B32,1),0) -> 1 | B32: 11391098 | C32: CRED OPR CONCILIAÇÃO | D32: 0 | E32: 435.65 | F32: 435.65 | G32: 0 | H32: 0
A33: =IF(LEN(B33)=8,LEFT(B33,1),0) -> 0 | B33: G517114 | C33: TÍTULOS E CRÉDITOS A | D33: 1724820.9 | E33: 20635.68 | F33: 18414.58 | G33: 2221.1 | H33: 1727042
A34: =IF(LEN(B34)=8,LEFT(B34,1),0) -> G | B34: G5171141 | C34: CRÉDITOS A RECEBER | D34: 148524.51 | E34: 7391.75 | F34: 9184.25 | G34: -1792.5 | H34: 146732.01
A35: =IF(LEN(B35)=8,LEFT(B35,1),0) -> 0 | B35: G51711418 | C35: OUTROS CRÉDITOS A RE | D35: 148524.51 | E35: 7391.75 | F35: 9184.25 | G35: -1792.5 | H35: 146732.01
A36: =IF(LEN(B36)=8,LEFT(B36,1),0) -> 1 | B36: 11610099 | C36: OUTROS CRÉD.RECEBER | D36: 148524.51 | E36: 7391.75 | F36: 9184.25 | G36: -1792.5 | H36: 146732.01
A37: =IF(LEN(B37)=8,LEFT(B37,1),0) -> G | B37: G5171144 | C37: CRÉDITOS TRIBUTÁRIOS | D37: 1576296.4 | E37: 13243.93 | F37: 9230.33 | G37: 4013.6 | H37: 1580310
A38: =IF(LEN(B38)=8,LEFT(B38,1),0) -> 0 | B38: G51711441 | C38: CRÉDITOS DE IMPOSTO | D38: 555471.6 | E38: 990.51 | F38: 0 | G38: 990.51 | H38: 556462.11
A39: =IF(LEN(B39)=8,LEFT(B39,1),0) -> 0 | B39: G517114411 | C39: IMPOSTO DE RENDA A C | D39: 555471.6 | E39: 990.51 | F39: 0 | G39: 990.51 | H39: 556462.11
A40: =IF(LEN(B40)=8,LEFT(B40,1),0) -> 1 | B40: 11641001 | C40: IRPJ A COMPENSAR CP | D40: 106126.2 | E40: 990.51 | F40: 0 | G40: 990.51 | H40: 107116.71
...

Sheet Bal 052026
B1: Table
C2: Exercício/período | D2: 005.2026 | E2: 005.2026 | F2: 005.2026 | G2: 005.2026 | H2: 005.2026
B3: Conta do Razão | D3: Saldo Anterior | E3: Débitos | F3: Créditos | G3: Movimento | H3: Saldo Acumulado
A4: =IF(LEN(B4)=8,LEFT(B4,1),0) -> 0 | B4: G517 | C4: PLANO DE CONTAS CONS | D4: 0 | E4: 616146.83 | F4: 616146.85 | G4: -0.02 | H4: -0.02
A5: =IF(LEN(B5)=8,LEFT(B5,1),0) -> 0 | B5: G5171 | C5: ATIVO | D5: 2822575 | E5: 477901.29 | F5: 390307.52 | G5: 87593.77 | H5: 2910168.8
A6: =IF(LEN(B6)=8,LEFT(B6,1),0) -> 0 | B6: G51711 | C6: CIRCULANTE | D6: 2489241.6 | E6: 477372.61 | F6: 378667.73 | G6: 98704.88 | H6: 2587946.5
A7: =IF(LEN(B7)=8,LEFT(B7,1),0) -> 0 | B7: G517111 | C7: DISPONÍVEL | D7: 119524.75 | E7: 331796.44 | F7: 245859.4 | G7: 85937.04 | H7: 205461.79
A8: =IF(LEN(B8)=8,LEFT(B8,1),0) -> G | B8: G5171113 | C8: BANCOS CONTA DEPÓSIT | D8: 119524.75 | E8: 331796.44 | F8: 245859.4 | G8: 85937.04 | H8: 205461.79
A9: =IF(LEN(B9)=8,LEFT(B9,1),0) -> 0 | B9: G51711131 | C9: BANCOS CONTA DEPÓSIT | D9: 119524.75 | E9: 331796.44 | F9: 245859.4 | G9: 85937.04 | H9: 205461.79
A10: =IF(LEN(B10)=8,LEFT(B10,1),0) -> 1 | B10: 11131050 | C10: BCO SANTANDER | D10: 57128.19 | E10: 27127.42 | F10: 13167.81 | G10: 13959.61 | H10: 71087.8
A11: =IF(LEN(B11)=8,LEFT(B11,1),0) -> 1 | B11: 11131090 | C11: BANCO SANTANDER | D11: 62805.43 | E11: 55683.79 | F11: 231.2 | G11: 55452.59 | H11: 118258.02
A12: =IF(LEN(B12)=8,LEFT(B12,1),0) -> 1 | B12: 11131091 | C12: BANCO SANTANDER | D12: 1 | E12: 16878.02 | F12: 370.67 | G12: 16507.35 | H12: 16508.35
A13: =IF(LEN(B13)=8,LEFT(B13,1),0) -> 1 | B13: 11132010 | C13: E341CC0008417/001791 | D13: 0 | E13: 99.56 | F13: 99.56 | G13: 0 | H13: 0
A14: =IF(LEN(B14)=8,LEFT(B14,1),0) -> 1 | B14: 11132050 | C14: BCO SANTANDER | D14: 0 | E14: 45503.48 | F14: 45503.48 | G14: 0 | H14: 0
A15: =IF(LEN(B15)=8,LEFT(B15,1),0) -> 1 | B15: 11132090 | C15: BANCO SANTANDER | D15: -409.87 | E15: 108364.88 | F15: 108347.39 | G15: 17.49 | H15: -392.38
A16: =IF(LEN(B16)=8,LEFT(B16,1),0) -> 1 | B16: 11132091 | C16: BANCO SANTANDER | D16: 0 | E16: 33757.5 | F16: 33757.5 | G16: 0 | H16: 0
A17: =IF(LEN(B17)=8,LEFT(B17,1),0) -> 1 | B17: 11133050 | C17: BCO SANTANDER SAIDA | D17: 0 | E17: 41493.36 | F17: 41493.36 | G17: 0 | H17: 0
A18: =IF(LEN(B18)=8,LEFT(B18,1),0) -> 1 | B18: 11133090 | C18: BANCO SANTANDER | D18: 0 | E18: 2888.43 | F18: 2888.43 | G18: 0 | H18: 0
A19: =IF(LEN(B19)=8,LEFT(B19,1),0) -> 0 | B19: G517112 | C19: APLICAÇÕES | D19: 614908.77 | E19: 6759.61 | F19: 5646.54 | G19: 1113.07 | H19: 616021.84
A20: =IF(LEN(B20)=8,LEFT(B20,1),0) -> G | B20: G5171126 | C20: QUOTAS DE FUNDOS DE | D20: 614908.77 | E20: 6759.61 | F20: 5646.54 | G20: 1113.07 | H20: 616021.84
A21: =IF(LEN(B21)=8,LEFT(B21,1),0) -> 0 | B21: G51711261 | C21: VINCULADAS À COBERTU | D21: 614908.77 | E21: 6759.61 | F21: 5646.54 | G21: 1113.07 | H21: 616021.84
A22: =IF(LEN(B22)=8,LEFT(B22,1),0) -> 0 | B22: G517112612 | C22: QUOTAS DE OUTROS FUN | D22: 614908.77 | E22: 6759.61 | F22: 5646.54 | G22: 1113.07 | H22: 616021.84
A23: =IF(LEN(B23)=8,LEFT(B23,1),0) -> 0 | B23: G5171126121 | C23: VALOR ORIGINAL | D23: 614908.77 | E23: 6759.61 | F23: 5646.54 | G23: 1113.07 | H23: 616021.84
A24: =IF(LEN(B24)=8,LEFT(B24,1),0) -> 1 | B24: 11240001 | C24: FD ÑEX CUV VC CP DPV | D24: 614908.77 | E24: 6759.61 | F24: 5646.54 | G24: 1113.07 | H24: 616021.84
A25: =IF(LEN(B25)=8,LEFT(B25,1),0) -> 0 | B25: G517113 | C25: CRÉDITOS DAS OPERAÇÕ | D25: 33118.5 | E25: 113299.57 | F25: 104776.07 | G25: 8523.5 | H25: 41642
A26: =IF(LEN(B26)=8,LEFT(B26,1),0) -> G | B26: G5171131 | C26: PRÊMIOS A RECEBER | D26: 33118.5 | E26: 87676.57 | F26: 79153.07 | G26: 8523.5 | H26: 41642
A27: =IF(LEN(B27)=8,LEFT(B27,1),0) -> 0 | B27: G51711311 | C27: DIRETO | D27: 33118.5 | E27: 87676.57 | F27: 79153.07 | G27: 8523.5 | H27: 41642
A28: =IF(LEN(B28)=8,LEFT(B28,1),0) -> 0 | B28: G517113111 | C28: PRÊMIOS - RISCOS VIG | D28: 33118.5 | E28: 87676.57 | F28: 79153.07 | G28: 8523.5 | H28: 41642
A29: =IF(LEN(B29)=8,LEFT(B29,1),0) -> 1 | B29: 11311011 | C29: SOMPO SEG REC RECEIT | D29: 0 | E29: 23127.07 | F29: 23127.07 | G29: 0 | H29: 0
A30: =IF(LEN(B30)=8,LEFT(B30,1),0) -> 1 | B30: 11311094 | C30: Clientes SompoRisk | D30: 33118.5 | E30: 64549.5 | F30: 56026 | G30: 8523.5 | H30: 41642
A31: =IF(LEN(B31)=8,LEFT(B31,1),0) -> G | B31: G5171138 | C31: OUTROS CRÉDITOS OPER | D31: 0 | E31: 25623 | F31: 25623 | G31: 0 | H31: 0
A32: =IF(LEN(B32)=8,LEFT(B32,1),0) -> 0 | B32: G51711388 | C32: OUTROS CRÉDITOS | D32: 0 | E32: 25623 | F32: 25623 | G32: 0 | H32: 0
A33: =IF(LEN(B33)=8,LEFT(B33,1),0) -> 1 | B33: 11391004 | C33: SALVADO VEND RECEBER | D33: 0 | E33: 25623 | F33: 25623 | G33: 0 | H33: 0
A34: =IF(LEN(B34)=8,LEFT(B34,1),0) -> 0 | B34: G517114 | C34: TÍTULOS E CRÉDITOS A | D34: 1721689.6 | E34: 25516.99 | F34: 22385.72 | G34: 3131.27 | H34: 1724820.9
A35: =IF(LEN(B35)=8,LEFT(B35,1),0) -> G | B35: G5171141 | C35: CRÉDITOS A RECEBER | D35: 158402.54 | E35: 6624.52 | F35: 16502.55 | G35: -9878.03 | H35: 148524.51
A36: =IF(LEN(B36)=8,LEFT(B36,1),0) -> 0 | B36: G51711418 | C36: OUTROS CRÉDITOS A RE | D36: 158402.54 | E36: 6624.52 | F36: 16502.55 | G36: -9878.03 | H36: 148524.51
A37: =IF(LEN(B37)=8,LEFT(B37,1),0) -> 1 | B37: 11610099 | C37: OUTROS CRÉD.RECEBER | D37: 158402.54 | E37: 6624.52 | F37: 16502.55 | G37: -9878.03 | H37: 148524.51
A38: =IF(LEN(B38)=8,LEFT(B38,1),0) -> G | B38: G5171144 | C38: CRÉDITOS TRIBUTÁRIOS | D38: 1563287.1 | E38: 18892.47 | F38: 5883.17 | G38: 13009.3 | H38: 1576296.4
A39: =IF(LEN(B39)=8,LEFT(B39,1),0) -> 0 | B39: G51711441 | C39: CRÉDITOS DE IMPOSTO | D39: 548878.77 | E39: 6592.83 | F39: 0 | G39: 6592.83 | H39: 555471.6
A40: =IF(LEN(B40)=8,LEFT(B40,1),0) -> 0 | B40: G517114411 | C40: IMPOSTO DE RENDA A C | D40: 548878.77 | E40: 6592.83 | F40: 0 | G40: 6592.83 | H40: 555471.6
...

Sheet Bal 042026
B1: Table
C2: Exercício/período | D2: 004.2026 | E2: 004.2026 | F2: 004.2026 | G2: 004.2026 | H2: 004.2026
B3: Conta do Razão | D3: Saldo Anterior | E3: Débitos | F3: Créditos | G3: Movimento | H3: Saldo Acumulado
A4: =IF(LEN(B4)=8,LEFT(B4,1),0) -> 0 | B4: G517 | C4: PLANO DE CONTAS CONS | D4: 0 | E4: 750863.5 | F4: 750863.5 | G4: 0 | H4: 0
A5: =IF(LEN(B5)=8,LEFT(B5,1),0) -> 0 | B5: G5171 | C5: ATIVO | D5: 2803994 | E5: 575790.38 | F5: 557209.35 | G5: 18581.03 | H5: 2822575
A6: =IF(LEN(B6)=8,LEFT(B6,1),0) -> 0 | B6: G51711 | C6: CIRCULANTE | D6: 2459549.5 | E6: 575261.7 | F6: 545569.56 | G6: 29692.14 | H6: 2489241.6
A7: =IF(LEN(B7)=8,LEFT(B7,1),0) -> 0 | B7: G517111 | C7: DISPONÍVEL | D7: 110572.37 | E7: 493181.4 | F7: 484229.02 | G7: 8952.38 | H7: 119524.75
A8: =IF(LEN(B8)=8,LEFT(B8,1),0) -> G | B8: G5171113 | C8: BANCOS CONTA DEPÓSIT | D8: 110572.37 | E8: 493181.4 | F8: 484229.02 | G8: 8952.38 | H8: 119524.75
A9: =IF(LEN(B9)=8,LEFT(B9,1),0) -> 0 | B9: G51711131 | C9: BANCOS CONTA DEPÓSIT | D9: 110572.37 | E9: 493181.4 | F9: 484229.02 | G9: 8952.38 | H9: 119524.75
A10: =IF(LEN(B10)=8,LEFT(B10,1),0) -> 1 | B10: 11131050 | C10: BCO SANTANDER | D10: 12296.21 | E10: 91639.79 | F10: 46807.81 | G10: 44831.98 | H10: 57128.19
A11: =IF(LEN(B11)=8,LEFT(B11,1),0) -> 1 | B11: 11131090 | C11: BANCO SANTANDER | D11: 98531.02 | E11: 44506.3 | F11: 80231.89 | G11: -35725.59 | H11: 62805.43
A12: =IF(LEN(B12)=8,LEFT(B12,1),0) -> 1 | B12: 11131091 | C12: BANCO SANTANDER | D12: 0 | E12: 1 | F12: 0 | G12: 1 | H12: 1
A13: =IF(LEN(B13)=8,LEFT(B13,1),0) -> 1 | B13: 11132050 | C13: BCO SANTANDER | D13: 0 | E13: 91639.79 | F13: 91639.79 | G13: 0 | H13: 0
A14: =IF(LEN(B14)=8,LEFT(B14,1),0) -> 1 | B14: 11132090 | C14: BANCO SANTANDER | D14: -255.86 | E14: 91966.9 | F14: 92120.91 | G14: -154.01 | H14: -409.87
A15: =IF(LEN(B15)=8,LEFT(B15,1),0) -> 1 | B15: 11132091 | C15: BANCO SANTANDER | D15: 0 | E15: 1 | F15: 1 | G15: 0 | H15: 0
A16: =IF(LEN(B16)=8,LEFT(B16,1),0) -> 1 | B16: 11133050 | C16: BCO SANTANDER SAIDA | D16: 1 | E16: 93426.62 | F16: 93427.62 | G16: -1 | H16: 0
A17: =IF(LEN(B17)=8,LEFT(B17,1),0) -> 1 | B17: 11133090 | C17: BANCO SANTANDER | D17: 0 | E17: 80000 | F17: 80000 | G17: 0 | H17: 0
A18: =IF(LEN(B18)=8,LEFT(B18,1),0) -> 0 | B18: G517112 | C18: APLICAÇÕES | D18: 608330.43 | E18: 6578.34 | F18: 0 | G18: 6578.34 | H18: 614908.77
A19: =IF(LEN(B19)=8,LEFT(B19,1),0) -> G | B19: G5171126 | C19: QUOTAS DE FUNDOS DE | D19: 608330.43 | E19: 6578.34 | F19: 0 | G19: 6578.34 | H19: 614908.77
A20: =IF(LEN(B20)=8,LEFT(B20,1),0) -> 0 | B20: G51711261 | C20: VINCULADAS À COBERTU | D20: 608330.43 | E20: 6578.34 | F20: 0 | G20: 6578.34 | H20: 614908.77
A21: =IF(LEN(B21)=8,LEFT(B21,1),0) -> 0 | B21: G517112612 | C21: QUOTAS DE OUTROS FUN | D21: 608330.43 | E21: 6578.34 | F21: 0 | G21: 6578.34 | H21: 614908.77
A22: =IF(LEN(B22)=8,LEFT(B22,1),0) -> 0 | B22: G5171126121 | C22: VALOR ORIGINAL | D22: 608330.43 | E22: 6578.34 | F22: 0 | G22: 6578.34 | H22: 614908.77
A23: =IF(LEN(B23)=8,LEFT(B23,1),0) -> 1 | B23: 11240001 | C23: FD ÑEX CUV VC CP DPV | D23: 608330.43 | E23: 6578.34 | F23: 0 | G23: 6578.34 | H23: 614908.77
A24: =IF(LEN(B24)=8,LEFT(B24,1),0) -> 0 | B24: G517113 | C24: CRÉDITOS DAS OPERAÇÕ | D24: 25093.5 | E24: 61659.73 | F24: 53634.73 | G24: 8025 | H24: 33118.5
A25: =IF(LEN(B25)=8,LEFT(B25,1),0) -> G | B25: G5171131 | C25: PRÊMIOS A RECEBER | D25: 25093.5 | E25: 61409.73 | F25: 53384.73 | G25: 8025 | H25: 33118.5
A26: =IF(LEN(B26)=8,LEFT(B26,1),0) -> 0 | B26: G51711311 | C26: DIRETO | D26: 25093.5 | E26: 61409.73 | F26: 53384.73 | G26: 8025 | H26: 33118.5
A27: =IF(LEN(B27)=8,LEFT(B27,1),0) -> 0 | B27: G517113111 | C27: PRÊMIOS - RISCOS VIG | D27: 25093.5 | E27: 61409.73 | F27: 53384.73 | G27: 8025 | H27: 33118.5
A28: =IF(LEN(B28)=8,LEFT(B28,1),0) -> 1 | B28: 11311011 | C28: SOMPO SEG REC RECEIT | D28: 0 | E28: 2559.73 | F28: 2559.73 | G28: 0 | H28: 0
A29: =IF(LEN(B29)=8,LEFT(B29,1),0) -> 1 | B29: 11311094 | C29: Clientes SompoRisk | D29: 25093.5 | E29: 58850 | F29: 50825 | G29: 8025 | H29: 33118.5
A30: =IF(LEN(B30)=8,LEFT(B30,1),0) -> G | B30: G5171138 | C30: OUTROS CRÉDITOS OPER | D30: 0 | E30: 250 | F30: 250 | G30: 0 | H30: 0
A31: =IF(LEN(B31)=8,LEFT(B31,1),0) -> 0 | B31: G51711388 | C31: OUTROS CRÉDITOS | D31: 0 | E31: 250 | F31: 250 | G31: 0 | H31: 0
A32: =IF(LEN(B32)=8,LEFT(B32,1),0) -> 1 | B32: 11391004 | C32: SALVADO VEND RECEBER | D32: 0 | E32: 250 | F32: 250 | G32: 0 | H32: 0
A33: =IF(LEN(B33)=8,LEFT(B33,1),0) -> 0 | B33: G517114 | C33: TÍTULOS E CRÉDITOS A | D33: 1715553.2 | E33: 13842.23 | F33: 7705.81 | G33: 6136.42 | H33: 1721689.6
A34: =IF(LEN(B34)=8,LEFT(B34,1),0) -> G | B34: G5171141 | C34: CRÉDITOS A RECEBER | D34: 155842.81 | E34: 2559.73 | F34: 0 | G34: 2559.73 | H34: 158402.54
A35: =IF(LEN(B35)=8,LEFT(B35,1),0) -> 0 | B35: G51711418 | C35: OUTROS CRÉDITOS A RE | D35: 155842.81 | E35: 2559.73 | F35: 0 | G35: 2559.73 | H35: 158402.54
A36: =IF(LEN(B36)=8,LEFT(B36,1),0) -> 1 | B36: 11610099 | C36: OUTROS CRÉD.RECEBER | D36: 155842.81 | E36: 2559.73 | F36: 0 | G36: 2559.73 | H36: 158402.54
A37: =IF(LEN(B37)=8,LEFT(B37,1),0) -> G | B37: G5171144 | C37: CRÉDITOS TRIBUTÁRIOS | D37: 1559710.4 | E37: 11282.5 | F37: 7705.81 | G37: 3576.69 | H37: 1563287.1
A38: =IF(LEN(B38)=8,LEFT(B38,1),0) -> 0 | B38: G51711441 | C38: CRÉDITOS DE IMPOSTO | D38: 548082.65 | E38: 796.12 | F38: 0 | G38: 796.12 | H38: 548878.77
A39: =IF(LEN(B39)=8,LEFT(B39,1),0) -> 0 | B39: G517114411 | C39: IMPOSTO DE RENDA A C | D39: 548082.65 | E39: 796.12 | F39: 0 | G39: 796.12 | H39: 548878.77
A40: =IF(LEN(B40)=8,LEFT(B40,1),0) -> 1 | B40: 11641001 | C40: IRPJ A COMPENSAR CP | D40: 104383.79 | E40: 796.12 | F40: 0 | G40: 796.12 | H40: 105179.91
...

Sheet Bal 032026
B1: Table
C2: Exercício/período | D2: 003.2026 | E2: 003.2026 | F2: 003.2026 | G2: 003.2026 | H2: 003.2026
B3: Conta do Razão | D3: Saldo Anterior | E3: Débitos | F3: Créditos | G3: Movimento | H3: Saldo Acumulado
A4: =IF(LEN(B4)=8,LEFT(B4,1),0) -> 0 | B4: C596 | C4: PLANO DE CONTAS SUSE | D4: -636846.24 | E4: 490521.67 | F4: 462323.14 | G4: 28198.53 | H4: -608647.71
A5: =IF(LEN(B5)=8,LEFT(B5,1),0) -> 0 | B5: C5961 | C5: ATIVO | D5: 2082079.4 | E5: 225066.96 | F5: 218569.97 | G5: 6496.99 | H5: 2088576.4
A6: =IF(LEN(B6)=8,LEFT(B6,1),0) -> 0 | B6: C59611 | C6: CIRCULANTE | D6: 1726523.8 | E6: 224538.28 | F6: 206930.18 | G6: 17608.1 | H6: 1744131.9
A7: =IF(LEN(B7)=8,LEFT(B7,1),0) -> 0 | B7: C596111 | C7: DISPONÍVEL | D7: 93261.73 | E7: 203797.86 | F7: 186487.22 | G7: 17310.64 | H7: 110572.37
A8: =IF(LEN(B8)=8,LEFT(B8,1),0) -> C | B8: C5961113 | C8: BANCOS CONTA DEPÓSIT | D8: 93261.73 | E8: 203797.86 | F8: 186487.22 | G8: 17310.64 | H8: 110572.37
A9: =IF(LEN(B9)=8,LEFT(B9,1),0) -> 0 | B9: C59611131 | C9: BANCOS CONTA DEPÓSIT | D9: 93261.73 | E9: 203797.86 | F9: 186487.22 | G9: 17310.64 | H9: 110572.37
A10: =IF(LEN(B10)=8,LEFT(B10,1),0) -> 1 | B10: 11131050 | C10: BCO SANTANDER | D10: 20105.37 | E10: 31639.79 | F10: 39448.95 | G10: -7809.16 | H10: 12296.21
A11: =IF(LEN(B11)=8,LEFT(B11,1),0) -> 1 | B11: 11131090 | C11: BANCO SANTANDER | D11: 73155.36 | E11: 25574.79 | F11: 199.13 | G11: 25375.66 | H11: 98531.02
A12: =IF(LEN(B12)=8,LEFT(B12,1),0) -> 1 | B12: 11132050 | C12: BCO SANTANDER | D12: 0 | E12: 31639.79 | F12: 31639.79 | G12: 0 | H12: 0
A13: =IF(LEN(B13)=8,LEFT(B13,1),0) -> 1 | B13: 11132090 | C13: BANCO SANTANDER | D13: 0 | E13: 36207.59 | F13: 36463.45 | G13: -255.86 | H13: -255.86
A14: =IF(LEN(B14)=8,LEFT(B14,1),0) -> 1 | B14: 11133050 | C14: BCO SANTANDER SAIDA | D14: 1 | E14: 78735.9 | F14: 78735.9 | G14: 0 | H14: 1
A15: =IF(LEN(B15)=8,LEFT(B15,1),0) -> 0 | B15: C596112 | C15: APLICAÇÕES | D15: 621246.46 | E15: 7276.93 | F15: 20192.96 | G15: -12916.03 | H15: 608330.43
A16: =IF(LEN(B16)=8,LEFT(B16,1),0) -> C | B16: C5961126 | C16: QUOTAS DE FUNDOS DE | D16: 621246.46 | E16: 7276.93 | F16: 20192.96 | G16: -12916.03 | H16: 608330.43
A17: =IF(LEN(B17)=8,LEFT(B17,1),0) -> 0 | B17: C59611261 | C17: VINCULADAS À COBERTU | D17: 621246.46 | E17: 7276.93 | F17: 20192.96 | G17: -12916.03 | H17: 608330.43
A18: =IF(LEN(B18)=8,LEFT(B18,1),0) -> 0 | B18: C596112612 | C18: QUOTAS DE OUTROS FUN | D18: 621246.46 | E18: 7276.93 | F18: 20192.96 | G18: -12916.03 | H18: 608330.43
A19: =IF(LEN(B19)=8,LEFT(B19,1),0) -> 0 | B19: C5961126121 | C19: VALOR ORIGINAL | D19: 621246.46 | E19: 7276.93 | F19: 20192.96 | G19: -12916.03 | H19: 608330.43
A20: =IF(LEN(B20)=8,LEFT(B20,1),0) -> 1 | B20: 11240001 | C20: FD ÑEX CUV VC CP DPV | D20: 621246.46 | E20: 7276.93 | F20: 20192.96 | G20: -12916.03 | H20: 608330.43
A21: =IF(LEN(B21)=8,LEFT(B21,1),0) -> 0 | B21: C596113 | C21: CRÉDITOS DAS OPERAÇÕ | D21: 0 | E21: 250 | F21: 250 | G21: 0 | H21: 0
A22: =IF(LEN(B22)=8,LEFT(B22,1),0) -> C | B22: C5961138 | C22: OUTROS CRÉDITOS OPER | D22: 0 | E22: 250 | F22: 250 | G22: 0 | H22: 0
A23: =IF(LEN(B23)=8,LEFT(B23,1),0) -> 0 | B23: C59611388 | C23: OUTROS CRÉDITOS | D23: 0 | E23: 250 | F23: 250 | G23: 0 | H23: 0
A24: =IF(LEN(B24)=8,LEFT(B24,1),0) -> 1 | B24: 11391004 | C24: SALVADO VEND RECEBER | D24: 0 | E24: 250 | F24: 250 | G24: 0 | H24: 0
A25: =IF(LEN(B25)=8,LEFT(B25,1),0) -> 0 | B25: C596114 | C25: TÍTULOS E CRÉDITOS A | D25: 1012015.6 | E25: 13213.49 | F25: 0 | G25: 13213.49 | H25: 1025229.1
A26: =IF(LEN(B26)=8,LEFT(B26,1),0) -> C | B26: C5961141 | C26: CRÉDITOS A RECEBER | D26: 151237.01 | E26: 4605.8 | F26: 0 | G26: 4605.8 | H26: 155842.81
A27: =IF(LEN(B27)=8,LEFT(B27,1),0) -> 0 | B27: C59611418 | C27: OUTROS CRÉDITOS A RE | D27: 151237.01 | E27: 4605.8 | F27: 0 | G27: 4605.8 | H27: 155842.81
A28: =IF(LEN(B28)=8,LEFT(B28,1),0) -> 1 | B28: 11610099 | C28: OUTROS CRÉD.RECEBER | D28: 151237.01 | E28: 4605.8 | F28: 0 | G28: 4605.8 | H28: 155842.81
A29: =IF(LEN(B29)=8,LEFT(B29,1),0) -> C | B29: C5961144 | C29: CRÉDITOS TRIBUTÁRIOS | D29: 860778.63 | E29: 8607.69 | F29: 0 | G29: 8607.69 | H29: 869386.32
A30: =IF(LEN(B30)=8,LEFT(B30,1),0) -> 0 | B30: C59611441 | C30: CRÉDITOS DE IMPOSTO | D30: 103313.68 | E30: 1070.11 | F30: 0 | G30: 1070.11 | H30: 104383.79
A31: =IF(LEN(B31)=8,LEFT(B31,1),0) -> 0 | B31: C596114411 | C31: IMPOSTO DE RENDA A C | D31: 103313.68 | E31: 1070.11 | F31: 0 | G31: 1070.11 | H31: 104383.79
A32: =IF(LEN(B32)=8,LEFT(B32,1),0) -> 1 | B32: 11641001 | C32: IRPJ A COMPENSAR CP | D32: 103313.68 | E32: 1070.11 | F32: 0 | G32: 1070.11 | H32: 104383.79
A33: =IF(LEN(B33)=8,LEFT(B33,1),0) -> 0 | B33: C59611442 | C33: CRÉDITOS DE CONTRIBU | D33: 757464.95 | E33: 7537.58 | F33: 0 | G33: 7537.58 | H33: 765002.53
A34: =IF(LEN(B34)=8,LEFT(B34,1),0) -> 0 | B34: C596114421 | C34: CONTRIBUIÇÃO SOCIAL | D34: 757464.95 | E34: 7537.58 | F34: 0 | G34: 7537.58 | H34: 765002.53
A35: =IF(LEN(B35)=8,LEFT(B35,1),0) -> 1 | B35: 11642001 | C35: CSLL A COMPENSAR CP | D35: 757464.95 | E35: 7537.58 | F35: 0 | G35: 7537.58 | H35: 765002.53
A36: =IF(LEN(B36)=8,LEFT(B36,1),0) -> 0 | B36: C59612 | C36: ATIVO NÃO CIRCULANTE | D36: 355555.57 | E36: 528.68 | F36: 11639.79 | G36: -11111.11 | H36: 344444.46
A37: =IF(LEN(B37)=8,LEFT(B37,1),0) -> 0 | B37: C596121 | C37: REALIZÁVEL A LONGO P | D37: 355555.57 | E37: 528.68 | F37: 11639.79 | G37: -11111.11 | H37: 344444.46
A38: =IF(LEN(B38)=8,LEFT(B38,1),0) -> C | B38: C5961213 | C38: TÍTULOS E CRÉDITOS A | D38: 355555.57 | E38: 528.68 | F38: 11639.79 | G38: -11111.11 | H38: 344444.46
A39: =IF(LEN(B39)=8,LEFT(B39,1),0) -> 0 | B39: C59612131 | C39: CRÉDITOS A RECEBER | D39: 355555.57 | E39: 528.68 | F39: 11639.79 | G39: -11111.11 | H39: 344444.46
A40: =IF(LEN(B40)=8,LEFT(B40,1),0) -> 0 | B40: C596121311 | C40: CRÉDITOS A RECEBER | D40: 355555.57 | E40: 528.68 | F40: 11639.79 | G40: -11111.11 | H40: 344444.46
...

Sheet Bal 022026
B1: Table
C2: Exercício/período | D2: 002.2026 | E2: 002.2026 | F2: 002.2026 | G2: 002.2026 | H2: 002.2026
B3: Conta do Razão | D3: Saldo Anterior | E3: Débitos | F3: Créditos | G3: Movimento | H3: Saldo Acumulado
A4: =IF(LEN(B4)=8,LEFT(B4,1),0) -> 0 | B4: C596 | C4: PLANO DE CONTAS SUSE | D4: -623154.73 | E4: 283399.58 | F4: 297091.09 | G4: -13691.51 | H4: -636846.24
A5: =IF(LEN(B5)=8,LEFT(B5,1),0) -> 0 | B5: C5961 | C5: ATIVO | D5: 2096637.8 | E5: 163626.94 | F5: 178185.32 | G5: -14558.38 | H5: 2082079.4
A6: =IF(LEN(B6)=8,LEFT(B6,1),0) -> 0 | B6: C59611 | C6: CIRCULANTE | D6: 1729971.1 | E6: 163098.26 | F6: 166545.53 | G6: -3447.27 | H6: 1726523.8
A7: =IF(LEN(B7)=8,LEFT(B7,1),0) -> 0 | B7: C596111 | C7: DISPONÍVEL | D7: 58364.98 | E7: 135355.77 | F7: 100459.02 | G7: 34896.75 | H7: 93261.73
A8: =IF(LEN(B8)=8,LEFT(B8,1),0) -> C | B8: C5961113 | C8: BANCOS CONTA DEPÓSIT | D8: 58364.98 | E8: 135355.77 | F8: 100459.02 | G8: 34896.75 | H8: 93261.73
A9: =IF(LEN(B9)=8,LEFT(B9,1),0) -> 0 | B9: C59611131 | C9: BANCOS CONTA DEPÓSIT | D9: 58364.98 | E9: 135355.77 | F9: 100459.02 | G9: 34896.75 | H9: 93261.73
A10: =IF(LEN(B10)=8,LEFT(B10,1),0) -> 1 | B10: 11131050 | C10: BCO SANTANDER | D10: 24208.48 | E10: 11639.79 | F10: 15742.9 | G10: -4103.11 | H10: 20105.37
A11: =IF(LEN(B11)=8,LEFT(B11,1),0) -> 1 | B11: 11131090 | C11: BANCO SANTANDER | D11: 52576.74 | E11: 20789.05 | F11: 210.43 | G11: 20578.62 | H11: 73155.36
A12: =IF(LEN(B12)=8,LEFT(B12,1),0) -> 1 | B12: 11132050 | C12: BCO SANTANDER | D12: -18421.24 | E12: 30061.03 | F12: 11639.79 | G12: 18421.24 | H12: 0
A13: =IF(LEN(B13)=8,LEFT(B13,1),0) -> 1 | B13: 11132090 | C13: BANCO SANTANDER | D13: 0 | E13: 41578.1 | F13: 41578.1 | G13: 0 | H13: 0
A14: =IF(LEN(B14)=8,LEFT(B14,1),0) -> 1 | B14: 11133050 | C14: BCO SANTANDER SAIDA | D14: 1 | E14: 31287.8 | F14: 31287.8 | G14: 0 | H14: 1
A15: =IF(LEN(B15)=8,LEFT(B15,1),0) -> 0 | B15: C596112 | C15: APLICAÇÕES | D15: 615094.05 | E15: 6152.41 | F15: 0 | G15: 6152.41 | H15: 621246.46
A16: =IF(LEN(B16)=8,LEFT(B16,1),0) -> C | B16: C5961126 | C16: QUOTAS DE FUNDOS DE | D16: 615094.05 | E16: 6152.41 | F16: 0 | G16: 6152.41 | H16: 621246.46
A17: =IF(LEN(B17)=8,LEFT(B17,1),0) -> 0 | B17: C59611261 | C17: VINCULADAS À COBERTU | D17: 615094.05 | E17: 6152.41 | F17: 0 | G17: 6152.41 | H17: 621246.46
A18: =IF(LEN(B18)=8,LEFT(B18,1),0) -> 0 | B18: C596112612 | C18: QUOTAS DE OUTROS FUN | D18: 615094.05 | E18: 6152.41 | F18: 0 | G18: 6152.41 | H18: 621246.46
A19: =IF(LEN(B19)=8,LEFT(B19,1),0) -> 0 | B19: C5961126121 | C19: VALOR ORIGINAL | D19: 615094.05 | E19: 6152.41 | F19: 0 | G19: 6152.41 | H19: 621246.46
A20: =IF(LEN(B20)=8,LEFT(B20,1),0) -> 1 | B20: 11240001 | C20: FD ÑEX CUV VC CP DPV | D20: 615094.05 | E20: 6152.41 | F20: 0 | G20: 6152.41 | H20: 621246.46
A21: =IF(LEN(B21)=8,LEFT(B21,1),0) -> 0 | B21: C596113 | C21: CRÉDITOS DAS OPERAÇÕ | D21: 0 | E21: 69 | F21: 69 | G21: 0 | H21: 0
A22: =IF(LEN(B22)=8,LEFT(B22,1),0) -> C | B22: C5961138 | C22: OUTROS CRÉDITOS OPER | D22: 0 | E22: 69 | F22: 69 | G22: 0 | H22: 0
A23: =IF(LEN(B23)=8,LEFT(B23,1),0) -> 0 | B23: C59611388 | C23: OUTROS CRÉDITOS | D23: 0 | E23: 69 | F23: 69 | G23: 0 | H23: 0
A24: =IF(LEN(B24)=8,LEFT(B24,1),0) -> 1 | B24: 11391004 | C24: SALVADO VEND RECEBER | D24: 0 | E24: 69 | F24: 69 | G24: 0 | H24: 0
A25: =IF(LEN(B25)=8,LEFT(B25,1),0) -> 0 | B25: C596114 | C25: TÍTULOS E CRÉDITOS A | D25: 1056512.1 | E25: 21521.08 | F25: 66017.51 | G25: -44496.43 | H25: 1012015.6
A26: =IF(LEN(B26)=8,LEFT(B26,1),0) -> C | B26: C5961141 | C26: CRÉDITOS A RECEBER | D26: 158968.63 | E26: 11896.75 | F26: 19628.37 | G26: -7731.62 | H26: 151237.01
A27: =IF(LEN(B27)=8,LEFT(B27,1),0) -> 0 | B27: C59611418 | C27: OUTROS CRÉDITOS A RE | D27: 158968.63 | E27: 11896.75 | F27: 19628.37 | G27: -7731.62 | H27: 151237.01
A28: =IF(LEN(B28)=8,LEFT(B28,1),0) -> 1 | B28: 11610099 | C28: OUTROS CRÉD.RECEBER | D28: 158968.63 | E28: 11896.75 | F28: 19628.37 | G28: -7731.62 | H28: 151237.01
A29: =IF(LEN(B29)=8,LEFT(B29,1),0) -> C | B29: C5961144 | C29: CRÉDITOS TRIBUTÁRIOS | D29: 897543.44 | E29: 9624.33 | F29: 46389.14 | G29: -36764.81 | H29: 860778.63
A30: =IF(LEN(B30)=8,LEFT(B30,1),0) -> 0 | B30: C59611441 | C30: CRÉDITOS DE IMPOSTO | D30: 134961.98 | E30: 884.38 | F30: 32532.68 | G30: -31648.3 | H30: 103313.68
A31: =IF(LEN(B31)=8,LEFT(B31,1),0) -> 0 | B31: C596114411 | C31: IMPOSTO DE RENDA A C | D31: 104635.13 | E31: 884.38 | F31: 2205.83 | G31: -1321.45 | H31: 103313.68
A32: =IF(LEN(B32)=8,LEFT(B32,1),0) -> 1 | B32: 11641001 | C32: IRPJ A COMPENSAR CP | D32: 104635.13 | E32: 884.38 | F32: 2205.83 | G32: -1321.45 | H32: 103313.68
A33: =IF(LEN(B33)=8,LEFT(B33,1),0) -> 0 | B33: C596114412 | C33: ANTECIPAÇÃO DE IMPOS | D33: 30326.85 | E33: 0 | F33: 30326.85 | G33: -30326.85 | H33: 0
A34: =IF(LEN(B34)=8,LEFT(B34,1),0) -> 1 | B34: 11641002 | C34: ANTECIPAÇÃO DE IRPJ | D34: 30326.85 | E34: 0 | F34: 30326.85 | G34: -30326.85 | H34: 0
A35: =IF(LEN(B35)=8,LEFT(B35,1),0) -> 0 | B35: C59611442 | C35: CRÉDITOS DE CONTRIBU | D35: 762581.46 | E35: 8739.95 | F35: 13856.46 | G35: -5116.51 | H35: 757464.95
A36: =IF(LEN(B36)=8,LEFT(B36,1),0) -> 0 | B36: C596114421 | C36: CONTRIBUIÇÃO SOCIAL | D36: 748725 | E36: 8739.95 | F36: 0 | G36: 8739.95 | H36: 757464.95
A37: =IF(LEN(B37)=8,LEFT(B37,1),0) -> 1 | B37: 11642001 | C37: CSLL A COMPENSAR CP | D37: 748725 | E37: 8739.95 | F37: 0 | G37: 8739.95 | H37: 757464.95
A38: =IF(LEN(B38)=8,LEFT(B38,1),0) -> 0 | B38: C596114422 | C38: ANTECIPAÇÃO DE CONTR | D38: 13856.46 | E38: 0 | F38: 13856.46 | G38: -13856.46 | H38: 0
A39: =IF(LEN(B39)=8,LEFT(B39,1),0) -> 1 | B39: 11642002 | C39: ANTECIPAÇÃO DE CSLL | D39: 13856.46 | E39: 0 | F39: 13856.46 | G39: -13856.46 | H39: 0
A40: =IF(LEN(B40)=8,LEFT(B40,1),0) -> 0 | B40: C59612 | C40: ATIVO NÃO CIRCULANTE | D40: 366666.68 | E40: 528.68 | F40: 11639.79 | G40: -11111.11 | H40: 355555.57
...

Sheet Bal 012026
B1: Table
C2: Exercício/período | D2: 001.2026 | E2: 001.2026 | F2: 001.2026 | G2: 001.2026 | H2: 001.2026
A3: =LEFT(B3,1) -> C | B3: Conta do Razão | D3: Saldo Anterior | E3: Débitos | F3: Créditos | G3: Movimento | H3: Saldo Acumulado
A4: =LEFT(B4,1) -> C | B4: C596 | C4: PLANO DE CONTAS SUSE | D4: -758085.45 | E4: 1327124.8 | F4: 1192194 | G4: 134930.72 | H4: -623154.73
A5: =LEFT(B5,1) -> C | B5: C5961 | C5: ATIVO | D5: 1960085.4 | E5: 769200 | F5: 632647.65 | G5: 136552.35 | H5: 2096637.8
A6: =LEFT(B6,1) -> C | B6: C59611 | C6: CIRCULANTE | D6: 1582307.6 | E6: 768671.32 | F6: 621007.86 | G6: 147663.46 | H6: 1729971.1
A7: =LEFT(B7,1) -> C | B7: C596111 | C7: DISPONÍVEL | D7: 8107.55 | E7: 671256.24 | F7: 620998.81 | G7: 50257.43 | H7: 58364.98
A8: =LEFT(B8,1) -> C | B8: C5961113 | C8: BANCOS CONTA DEPÓSIT | D8: 8107.55 | E8: 671256.24 | F8: 620998.81 | G8: 50257.43 | H8: 58364.98
A9: =LEFT(B9,1) -> C | B9: C59611131 | C9: BANCOS CONTA DEPÓSIT | D9: 8107.55 | E9: 671256.24 | F9: 620998.81 | G9: 50257.43 | H9: 58364.98
A10: =LEFT(B10,1) -> 1 | B10: 11131050 | C10: BCO SANTANDER | D10: 15479.85 | E10: 109949.19 | F10: 101220.56 | G10: 8728.63 | H10: 24208.48
A11: =LEFT(B11,1) -> 1 | B11: 11131090 | C11: BANCO SANTANDER | D11: 9954.11 | E11: 42818.33 | F11: 195.7 | G11: 42622.63 | H11: 52576.74
A12: =LEFT(B12,1) -> 1 | B12: 11132050 | C12: BCO SANTANDER | D12: -17317.36 | E12: 311733.68 | F12: 312837.56 | G12: -1103.88 | H12: -18421.24
A13: =LEFT(B13,1) -> 1 | B13: 11132090 | C13: BANCO SANTANDER | D13: -9.05 | E13: 84489.14 | F13: 84480.09 | G13: 9.05 | H13: 0
A14: =LEFT(B14,1) -> 1 | B14: 11133050 | C14: BCO SANTANDER SAIDA | D14: 0 | E14: 122257.12 | F14: 122256.12 | G14: 1 | H14: 1
A15: =LEFT(B15,1) -> 1 | B15: 11133090 | C15: BANCO SANTANDER | D15: 0 | E15: 8.78 | F15: 8.78 | G15: 0 | H15: 0
A16: =LEFT(B16,1) -> C | B16: C596112 | C16: APLICAÇÕES | D16: 528893.79 | E16: 86200.26 | F16: 0 | G16: 86200.26 | H16: 615094.05
A17: =LEFT(B17,1) -> C | B17: C5961126 | C17: QUOTAS DE FUNDOS DE | D17: 528893.79 | E17: 86200.26 | F17: 0 | G17: 86200.26 | H17: 615094.05
A18: =LEFT(B18,1) -> C | B18: C59611261 | C18: VINCULADAS À COBERTU | D18: 528893.79 | E18: 86200.26 | F18: 0 | G18: 86200.26 | H18: 615094.05
A19: =LEFT(B19,1) -> C | B19: C596112612 | C19: QUOTAS DE OUTROS FUN | D19: 528893.79 | E19: 86200.26 | F19: 0 | G19: 86200.26 | H19: 615094.05
A20: =LEFT(B20,1) -> C | B20: C5961126121 | C20: VALOR ORIGINAL | D20: 528893.79 | E20: 86200.26 | F20: 0 | G20: 86200.26 | H20: 615094.05
A21: =LEFT(B21,1) -> 1 | B21: 11240001 | C21: FD ÑEX CUV VC CP DPV | D21: 528893.79 | E21: 86200.26 | F21: 0 | G21: 86200.26 | H21: 615094.05
A22: =LEFT(B22,1) -> C | B22: C596113 | C22: CRÉDITOS DAS OPERAÇÕ | D22: 0 | E22: 9.05 | F22: 9.05 | G22: 0 | H22: 0
A23: =LEFT(B23,1) -> C | B23: C5961138 | C23: OUTROS CRÉDITOS OPER | D23: 0 | E23: 9.05 | F23: 9.05 | G23: 0 | H23: 0
A24: =LEFT(B24,1) -> C | B24: C59611388 | C24: OUTROS CRÉDITOS | D24: 0 | E24: 9.05 | F24: 9.05 | G24: 0 | H24: 0
A25: =LEFT(B25,1) -> 1 | B25: 11391098 | C25: CRED OPR CONCILIAÇÃO | D25: 0 | E25: 9.05 | F25: 9.05 | G25: 0 | H25: 0
A26: =LEFT(B26,1) -> C | B26: C596114 | C26: TÍTULOS E CRÉDITOS A | D26: 1045306.3 | E26: 11205.77 | F26: 0 | G26: 11205.77 | H26: 1056512.1
A27: =LEFT(B27,1) -> C | B27: C5961141 | C27: CRÉDITOS A RECEBER | D27: 158968.63 | E27: 0 | F27: 0 | G27: 0 | H27: 158968.63
A28: =LEFT(B28,1) -> C | B28: C59611418 | C28: OUTROS CRÉDITOS A RE | D28: 158968.63 | E28: 0 | F28: 0 | G28: 0 | H28: 158968.63
A29: =LEFT(B29,1) -> 1 | B29: 11610099 | C29: OUTROS CRÉD.RECEBER | D29: 158968.63 | E29: 0 | F29: 0 | G29: 0 | H29: 158968.63
A30: =LEFT(B30,1) -> C | B30: C5961144 | C30: CRÉDITOS TRIBUTÁRIOS | D30: 886337.67 | E30: 11205.77 | F30: 0 | G30: 11205.77 | H30: 897543.44
A31: =LEFT(B31,1) -> C | B31: C59611441 | C31: CRÉDITOS DE IMPOSTO | D31: 131562.4 | E31: 3399.58 | F31: 0 | G31: 3399.58 | H31: 134961.98
A32: =LEFT(B32,1) -> C | B32: C596114411 | C32: IMPOSTO DE RENDA A C | D32: 101235.55 | E32: 3399.58 | F32: 0 | G32: 3399.58 | H32: 104635.13
A33: =LEFT(B33,1) -> 1 | B33: 11641001 | C33: IRPJ A COMPENSAR CP | D33: 101235.55 | E33: 3399.58 | F33: 0 | G33: 3399.58 | H33: 104635.13
A34: =LEFT(B34,1) -> C | B34: C596114412 | C34: ANTECIPAÇÃO DE IMPOS | D34: 30326.85 | E34: 0 | F34: 0 | G34: 0 | H34: 30326.85
A35: =LEFT(B35,1) -> 1 | B35: 11641002 | C35: ANTECIPAÇÃO DE IRPJ | D35: 30326.85 | E35: 0 | F35: 0 | G35: 0 | H35: 30326.85
A36: =LEFT(B36,1) -> C | B36: C59611442 | C36: CRÉDITOS DE CONTRIBU | D36: 754775.27 | E36: 7806.19 | F36: 0 | G36: 7806.19 | H36: 762581.46
A37: =LEFT(B37,1) -> C | B37: C596114421 | C37: CONTRIBUIÇÃO SOCIAL | D37: 740918.81 | E37: 7806.19 | F37: 0 | G37: 7806.19 | H37: 748725
A38: =LEFT(B38,1) -> 1 | B38: 11642001 | C38: CSLL A COMPENSAR CP | D38: 740918.81 | E38: 7806.19 | F38: 0 | G38: 7806.19 | H38: 748725
A39: =LEFT(B39,1) -> C | B39: C596114422 | C39: ANTECIPAÇÃO DE CONTR | D39: 13856.46 | E39: 0 | F39: 0 | G39: 0 | H39: 13856.46
A40: =LEFT(B40,1) -> 1 | B40: 11642002 | C40: ANTECIPAÇÃO DE CSLL | D40: 13856.46 | E40: 0 | F40: 0 | G40: 0 | H40: 13856.46
...

Sheet Bal 12.2026
H28: =G27+G28 -> 0
H30: =G29+G30 -> 0

Sheet Bal 11.2026
H28: =G27+G28 -> 0
H30: =G29+G30 -> 0

Sheet Bal 10.2026
H28: =G27+G28 -> 0
H30: =G29+G30 -> 0

Sheet Bal 09.2026

Sheet Bal 08.2026

Sheet Bal 07.2026
