Workbook

Sheet Resumo
B3: Faturamento Anual
B4: Sompo Services
B7: COMP | C7: VALOR BRUTO | D7: RET ISS | E7: RET FED | F7: VALOR LÍQUIDO
B8: 46023
B9: 46054
B10: 46082
B11: 46113
B12: 46143
B13: 46174
B14: 46204
B15: 46235
B16: 46266
B17: 46296
B18: 46327
B19: 46357
B20: TOTAL | C20: =SUM(C8:C19) -> 0 | D20: =SUM(D8:D19) -> 0 | E20: =SUM(E8:E19) -> 0 | F20: =SUM(F8:F19) -> 0

Sheet FATURAMENTO
A1: Faturamento e Apuração dos Tributos - Notas Fiscais emitidas
A2: SOMPO SERVICES GESTAO DE RISCOS E VISTORIA LTDA | K2: 46.206.637/0001-30
A4: COMP EMISSÃO | B4: DATA EMISSÃO | C4: Prefeitura | D4: Nº NF | E4: Numero SAP | F4: Valor N. Fiscal | G4: ISS - 5% | H4: IRRF - 1,5% | I4: CSLL - 1% | J4: COFINS- 3% | K4: PIS- 0,65% | L4: TOTAL CSRF | M4: Valor | N4: DOC REC BANCO | O4: Dt. Dep. | P4: COMP RECEBIMENTO | Q4: Cód | R4: BP | S4: Razão | T4: CNPJ | U4: REGIME | V4: CONTA BANCO
A5: =TEXT(B5,"mm/aaaa") -> 01/2026 | B5: 46028 | C5: SP | D5: 248 | E5: 1800000015 | F5: 547.5 | G5: 0 | H5: 0 | I5: =ROUND(F5*1%,2) -> 5.48 | J5: =ROUND(F5*3%,2) -> 16.43 | K5: =ROUND(F5*0.65%,2) -> 3.56 | L5: =SUM(I5:K5) -> 25.47 | M5: =F5-H5-I5-J5-K5 -> 522.03 | N5: 1400000015 | O5: 46043 | P5: =TEXT(O5,"mm/aaaa") -> 01/2026 | Q5: TELERISCO | R5: 1002640697 | S5: COOP DE TRANSP AUTONOMOS DE BENS DE SALTO E REGIAO | T5: 5370882000109 | U5: NÃO optante pelo Simples Nacional | V5: 11311094
A6: =TEXT(B6,"mm/aaaa") -> 01/2026 | B6: 46028 | C6: SP | D6: 249 | E6: 1800000000 | F6: 20758.5 | G6: 0 | H6: =ROUND(F6*1.5%,2) -> 311.38 | I6: =ROUND(F6*1%,2) -> 207.59 | J6: =ROUND(F6*3%,2) -> 622.76 | K6: =ROUND(F6*0.65%,2) -> 134.93 | L6: =SUM(I6:K6) -> 965.28 | M6: =F6-H6-I6-J6-K6 -> 19481.84 | N6: 1400000030 | O6: 46043 | P6: =TEXT(O6,"mm/aaaa") -> 01/2026 | Q6: TELERISCO | R6: 1001187614 | S6: INTEGRA BRASIL TRANSPORTES LTDA | T6: 9395767000131 | U6: NÃO optante pelo Simples Nacional | V6: 11311094
A7: =TEXT(B7,"mm/aaaa") -> 01/2026 | B7: 46028 | C7: SP | D7: 250 | E7: 1800000045 | F7: 1242 | G7: 0 | H7: =ROUND(F7*1.5%,2) -> 18.63 | I7: =ROUND(F7*1%,2) -> 12.42 | J7: =ROUND(F7*3%,2) -> 37.26 | K7: =ROUND(F7*0.65%,2) -> 8.07 | L7: =SUM(I7:K7) -> 57.75 | M7: =F7-H7-I7-J7-K7 -> 1165.62 | N7: 1400000045 | O7: 46043 | P7: =TEXT(O7,"mm/aaaa") -> 01/2026 | Q7: TELERISCO | R7: 1014825740 | S7: PC LOGISTICA LTDA | T7: 44120318000181 | U7: NÃO optante pelo Simples Nacional | V7: 11311094
A8: =TEXT(B8,"mm/aaaa") -> 01/2026 | B8: 46028 | C8: SP | D8: 251 | E8: 1800000016 | F8: 11366 | G8: 0 | H8: =ROUND(F8*1.5%,2) -> 170.49 | I8: =ROUND(F8*1%,2) -> 113.66 | J8: =ROUND(F8*3%,2) -> 340.98 | K8: =ROUND(F8*0.65%,2) -> 73.88 | L8: =SUM(I8:K8) -> 528.52 | M8: =F8-H8-I8-J8-K8 -> 10666.99 | N8: 1400000016 | O8: 46043 | P8: =TEXT(O8,"mm/aaaa") -> 01/2026 | Q8: TELERISCO | R8: 1008259405 | S8: SENSITIVE TRANSPORTES LTDA ME | T8: 28759933000186 | U8: NÃO optante pelo Simples Nacional | V8: 11311094
A9: =TEXT(B9,"mm/aaaa") -> 01/2026 | B9: 46028 | C9: SP | D9: 252 | E9: 1800000030 | F9: 3233.5 | G9: 0 | H9: =ROUND(F9*1.5%,2) -> 48.5 | I9: =ROUND(F9*1%,2) -> 32.34 | J9: =ROUND(F9*3%,2) -> 97.01 | K9: =ROUND(F9*0.65%,2) -> 21.02 | L9: =SUM(I9:K9) -> 150.37 | M9: =F9-H9-I9-J9-K9 -> 3034.63 | N9: 1400000060 | O9: 46043 | P9: =TEXT(O9,"mm/aaaa") -> 01/2026 | Q9: TELERISCO | R9: 1007834227 | S9: ZANIN TRANSPORTES E LOGISTICA LTDA | T9: 14457026000178 | U9: NÃO optante pelo Simples Nacional | V9: 11311094
A10: =TEXT(B10,"mm/aaaa") -> 01/2026 | B10: 46053 | C10: SP | D10: 253 | E10: 0 | F10: 0 | G10: =F10*5% -> 0 | H10: =ROUND(F10*1.5%,2) -> 0 | I10: =ROUND(F10*1%,2) -> 0 | J10: =ROUND(F10*3%,2) -> 0 | K10: =ROUND(F10*0.65%,2) -> 0 | L10: =SUM(I10:K10) -> 0 | M10: CANCELADA | N10: 0 | O10: 0 | P10: 0 | Q10: TELERISCO | R10: 0 | S10: 0 | T10: 0 | U10: N/A | V10: 11311094
A11: =TEXT(B11,"mm/aaaa") -> 01/2026 | B11: 46053 | C11: SP | D11: 254 | E11: 0 | F11: 0 | G11: =F11*5% -> 0 | H11: =ROUND(F11*1.5%,2) -> 0 | I11: =ROUND(F11*1%,2) -> 0 | J11: =ROUND(F11*3%,2) -> 0 | K11: =ROUND(F11*0.65%,2) -> 0 | L11: =SUM(I11:K11) -> 0 | M11: CANCELADA | N11: 0 | O11: 0 | P11: 0 | Q11: TELERISCO | R11: 0 | S11: 0 | T11: 0 | U11: N/A | V11: 11311094
A12: =TEXT(B12,"mm/aaaa") -> 01/2026 | B12: 46053 | C12: SP | D12: 255 | E12: 0 | F12: 0 | G12: =F12*5% -> 0 | H12: =ROUND(F12*1.5%,2) -> 0 | I12: =ROUND(F12*1%,2) -> 0 | J12: =ROUND(F12*3%,2) -> 0 | K12: =ROUND(F12*0.65%,2) -> 0 | L12: =SUM(I12:K12) -> 0 | M12: CANCELADA | N12: 0 | O12: 0 | P12: 0 | Q12: TELERISCO | R12: 0 | S12: 0 | T12: 0 | U12: N/A | V12: 11311094
A13: =TEXT(B13,"mm/aaaa") -> 01/2026 | B13: 46048 | C13: SP | D13: 256 | E13: 1800000075 | F13: 7990.17 | G13: 0 | H13: =ROUND(F13*1.5%,2) -> 119.85 | I13: =ROUND(F13*1%,2) -> 79.9 | J13: =ROUND(F13*3%,2) -> 239.71 | K13: =ROUND(F13*0.65%,2) -> 51.94 | L13: =SUM(I13:K13) -> 371.55 | M13: =F13-H13-I13-J13-K13 -> 7498.77 | N13: 1400000660 | O13: 46155 | P13: 05/2026 | Q13: 3115 | R13: 1007620183 | S13: GOLDEN SAT | T13: 9446817000162 | U13: NÃO optante pelo Simples Nacional | V13: 11132050
A14: =TEXT(B14,"mm/aaaa") -> 02/2026 | B14: 46061 | C14: SP | D14: 257 | E14: 0 | F14: 0 | H14: =ROUND(F14*1.5%,2) -> 0 | I14: =ROUND(F14*1%,2) -> 0 | J14: =ROUND(F14*3%,2) -> 0 | K14: =ROUND(F14*0.65%,2) -> 0 | L14: =SUM(I14:K14) -> 0 | M14: CANCELADA | N14: 0 | O14: 0 | P14: 0 | Q14: TELERISCO | R14: 0 | S14: 0 | T14: 0 | U14: N/A | V14: 11311094
A15: =TEXT(B15,"mm/aaaa") -> 02/2026 | B15: 46061 | C15: SP | D15: 258 | E15: 1800000090 | F15: 16005.5 | H15: =ROUND(F15*1.5%,2) -> 240.08 | I15: =ROUND(F15*1%,2) -> 160.06 | J15: =ROUND(F15*3%,2) -> 480.17 | K15: =ROUND(F15*0.65%,2) -> 104.04 | L15: =SUM(I15:K15) -> 744.27 | M15: =F15-H15-I15-J15-K15 -> 15021.15 | N15: 1400000105 | O15: 46079 | P15: =TEXT(O15,"mm/aaaa") -> 02/2026 | Q15: TELERISCO | R15: 1001187614 | S15: INTEGRA BRASIL TRANSPORTES LTDA | T15: 9395767000131 | U15: NÃO optante pelo Simples Nacional | V15: 11311094
A16: =TEXT(B16,"mm/aaaa") -> 02/2026 | B16: 46062 | C16: SP | D16: 259 | E16: 1800000151 | F16: 69 | H16: 0 | I16: 0 | J16: 0 | K16: 0 | L16: =SUM(I16:K16) -> 0 | M16: =F16-H16-I16-J16-K16 -> 69 | N16: 1400000150 | O16: 46079 | P16: =TEXT(O16,"mm/aaaa") -> 02/2026 | Q16: TELERISCO | R16: 1018345066 | S16: TRANSPORTADORA ANDARILHO LTDA | T16: 57904437000177 | U16: Optante pelo Simples Nacional desde 30/10/2024 | V16: 11311094
A17: =TEXT(B17,"mm/aaaa") -> 02/2026 | B17: 46062 | C17: SP | D17: 260 | E17: 1800000105 | F17: 3540.5 | H17: =ROUND(F17*1.5%,2) -> 53.11 | I17: =ROUND(F17*1%,2) -> 35.41 | J17: =ROUND(F17*3%,2) -> 106.22 | K17: =ROUND(F17*0.65%,2) -> 23.01 | L17: =SUM(I17:K17) -> 164.64 | M17: =F17-H17-I17-J17-K17 -> 3322.75 | N17: 1400000120 | O17: 46079 | P17: =TEXT(O17,"mm/aaaa") -> 02/2026 | Q17: TELERISCO | R17: 1008259405 | S17: SENSITIVE TRANSPORTES LTDA ME | T17: 28759933000186 | U17: NÃO optante pelo Simples Nacional | V17: 11311094
A18: =TEXT(B18,"mm/aaaa") -> 02/2026 | B18: 46062 | C18: SP | D18: 261 | E18: 1800000120 | F18: 15850 | H18: =ROUND(F18*1.5%,2) -> 237.75 | I18: =ROUND(F18*1%,2) -> 158.5 | J18: =ROUND(F18*3%,2) -> 475.5 | K18: =ROUND(F18*0.65%,2) -> 103.03 | L18: =SUM(I18:K18) -> 737.03 | M18: =F18-H18-I18-J18-K18+0.01 -> 14875.23 | O18: EM ABERTO | Q18: TELERISCO | R18: 1018075263 | S18: TRILOG EXPRESS LTDA | T18: 58578490000198 | U18: NÃO optante pelo Simples Nacional | V18: 11311094
A19: =TEXT(B19,"mm/aaaa") -> 02/2026 | B19: 46062 | C19: SP | D19: 262 | E19: 1800000121 | F19: 2424.5 | H19: =ROUND(F19*1.5%,2) -> 36.37 | I19: =ROUND(F19*1%,2) -> 24.25 | J19: =ROUND(F19*3%,2) -> 72.74 | K19: =ROUND(F19*0.65%,2) -> 15.76 | L19: =SUM(I19:K19) -> 112.75 | M19: =F19-H19-I19-J19-K19 -> 2275.38 | O19: EM ABERTO | Q19: TELERISCO | R19: 1014825740 | S19: PC LOGISTICA LTDA | T19: 44120318000181 | U19: NÃO optante pelo Simples Nacional | V19: 11311094
A20: =TEXT(B20,"mm/aaaa") -> 02/2026 | B20: 46062 | C20: SP | D20: 263 | E20: 1800000135 | F20: 250 | H20: 0 | I20: =ROUND(F20*1%,2) -> 2.5 | J20: =ROUND(F20*3%,2) -> 7.5 | K20: =ROUND(F20*0.65%,2) -> 1.63 | L20: =SUM(I20:K20) -> 11.63 | M20: =F20-H20-I20-J20-K20 -> 238.37 | N20: 1400000135 | O20: 46079 | P20: =TEXT(O20,"mm/aaaa") -> 02/2026 | Q20: TELERISCO | R20: 1002640697 | S20: COOP DE TRANSP AUTONOMOS DE BENS DE SALTO E REGIAO | T20: 5370882000109 | U20: NÃO optante pelo Simples Nacional | V20: 11311094
A21: =TEXT(B21,"mm/aaaa") -> 02/2026 | B21: 46062 | C21: SP | D21: 264 | E21: 1800000122 | F21: 571 | H21: 0 | I21: =ROUND(F21*1%,2) -> 5.71 | J21: =ROUND(F21*3%,2) -> 17.13 | K21: =ROUND(F21*0.65%,2) -> 3.71 | L21: =SUM(I21:K21) -> 26.55 | M21: =F21-H21-I21-J21-K21 -> 544.45 | N21: 1400000165 | O21: 46080 | P21: =TEXT(O21,"mm/aaaa") -> 02/2026 | Q21: TELERISCO | R21: 1017716043 | S21: ANSELMINI RODOVIARIO LTDA | T21: 57951895000167 | U21: NÃO optante pelo Simples Nacional | V21: 11311094
A22: =TEXT(B22,"mm/aaaa") -> 02/2026 | B22: 46062 | C22: SP | D22: 265 | E22: 1800000150 | F22: 1458.5 | H22: =ROUND(F22*1.5%,2) -> 21.88 | I22: =ROUND(F22*1%,2) -> 14.59 | J22: =ROUND(F22*3%,2) -> 43.76 | K22: =ROUND(F22*0.65%,2) -> 9.48 | L22: =SUM(I22:K22) -> 67.83 | M22: =F22-H22-I22-J22-K22 -> 1368.79 | N22: 1400000136 | O22: 46079 | P22: =TEXT(O22,"mm/aaaa") -> 02/2026 | Q22: TELERISCO | R22: 1007834227 | S22: ZANIN TRANSPORTES E LOGISTICA LTDA | T22: 14457026000178 | U22: NÃO optante pelo Simples Nacional | V22: 11311094
A23: =TEXT(B23,"mm/aaaa") -> 02/2026 | B23: 46062 | C23: SP | D23: 266 | E23: 1800000123 | F23: 235.5 | H23: 0 | I23: =ROUND(F23*1%,2) -> 2.36 | J23: =ROUND(F23*3%,2) -> 7.07 | K23: =ROUND(F23*0.65%,2) -> 1.53 | L23: =SUM(I23:K23) -> 10.96 | M23: =F23-H23-I23-J23-K23 -> 224.54 | N23: 1400000166 | O23: 46080 | P23: =TEXT(O23,"mm/aaaa") -> 02/2026 | Q23: TELERISCO | R23: 1018930052 | S23: HE TRANSPORTES LTDA | T23: 45916594000113 | U23: NÃO optante pelo Simples Nacional | V23: 11311094
A24: =TEXT(B24,"mm/aaaa") -> 02/2026 | B24: 46062 | C24: SP | D24: 267 | E24: 1800000152 | F24: 78.5 | H24: 0 | I24: 0 | J24: 0 | K24: 0 | L24: =SUM(I24:K24) -> 0 | M24: =F24-H24-I24-J24-K24 -> 78.5 | N24: 1400000255 | O24: 46112 | P24: =TEXT(O24,"mm/aaaa") -> 03/2026 | Q24: TELERISCO | R24: 1017130541 | S24: TRANSPACKLOG TRANSPORTE DE CARGAS LTDA | T24: 53045500000106 | U24: Optante pelo Simples Nacional desde 01/01/2024 | V24: 11311094
A25: =TEXT(B25,"mm/aaaa") -> 02/2026 | B25: 46062 | C25: SP | D25: 268 | E25: 1800000106 | F25: 69 | H25: 0 | I25: 0 | J25: 0 | K25: 0 | L25: =SUM(I25:K25) -> 0 | M25: =F25-H25-I25-J25-K25 -> 69 | N25: =VLOOKUP(E25,'[2]Controle Sompo Risks'!$H:$I,2,0) -> 1400000750 | O25: 46198 | P25: 06/2026 | Q25: TELERISCO | R25: 1018840151 | S25: EAGLE GROUP TECHNOLOGIES LOGISTICS E TRANSPORTS LTDA | T25: 55365607000167 | U25: Optante pelo Simples Nacional | V25: 11311094
A26: =TEXT(B26,"mm/aaaa") -> 02/2026 | B26: 46079 | C26: SP | D26: 269 | E26: 1800000165 | F26: 3906.58 | H26: =ROUND(F26*1.5%,2) -> 58.6 | I26: =ROUND(F26*1%,2) -> 39.07 | J26: =ROUND(F26*3%,2) -> 117.2 | K26: =ROUND(F26*0.65%,2) -> 25.39 | L26: =SUM(I26:K26) -> 181.66 | M26: =F26-H26-I26-J26-K26 -> 3666.32 | N26: 1400000660 | O26: 46162 | P26: 05/2026 | Q26: 3115 | R26: 1007620183 | S26: GOLDEN SAT | T26: 9446817000162 | U26: NÃO optante pelo Simples Nacional | V26: 11132050
A27: =TEXT(B27,"mm/aaaa") -> 03/2026 | B27: 46086 | C27: SP | D27: 270 | E27: 1800000241 | F27: 138 | H27: 0 | I27: 0 | J27: 0 | K27: 0 | L27: =SUM(I27:K27) -> 0 | M27: =F27-H27-I27-J27-K27 -> 138 | N27: 1400000211 | O27: 46107 | P27: =TEXT(O27,"mm/aaaa") -> 03/2026 | Q27: TELERISCO | R27: 1018645192 | S27: SUNO DISTRIBUIDORA SOLAR LTDA | T27: 32764816000188 | U27: NÃO optante pelo Simples Nacional | V27: 11311094
A28: =TEXT(B28,"mm/aaaa") -> 03/2026 | B28: 46086 | C28: SP | D28: 271 | E28: 1800000270 | F28: 254.5 | H28: 0 | I28: =ROUND(F28*1%,2) -> 2.55 | J28: =ROUND(F28*3%,2) -> 7.64 | K28: =ROUND(F28*0.65%,2) -> 1.65 | L28: =SUM(I28:K28) -> 11.84 | M28: =F28-H28-I28-J28-K28 -> 242.66 | N28: 1400000436 | O28: 46148 | P28: 05/2026 | Q28: TELERISCO | R28: 1016771816 | S28: UNNI SOLUCOES LOGISTICAS LTDA | T28: 41607658000143 | U28: NÃO optante pelo Simples Nacional | V28: 11311094
A29: =TEXT(B29,"mm/aaaa") -> 03/2026 | B29: 46086 | C29: SP | D29: 272 | E29: 1800000257 | F29: 250 | H29: 0 | I29: 0 | J29: 0 | K29: 0 | L29: =SUM(I29:K29) -> 0 | M29: =F29-H29-I29-J29-K29 -> 250 | N29: 1400000181 | O29: 46107 | P29: =TEXT(O29,"mm/aaaa") -> 03/2026 | Q29: TELERISCO | R29: 1017130541 | S29: TRANSPACKLOG TRANSPORTE DE CARGAS LTDA | T29: 53045500000106 | U29: Optante pelo Simples Nacional desde 01/01/2024 | V29: 11311094
A30: =TEXT(B30,"mm/aaaa") -> 03/2026 | B30: 46086 | C30: SP | D30: 273 | E30: 1800000286 | F30: 250 | H30: 0 | I30: 0 | J30: 0 | K30: 0 | L30: =SUM(I30:K30) -> 0 | M30: =F30-H30-I30-J30-K30 -> 250 | N30: 1400000240 | O30: 46107 | P30: =TEXT(O30,"mm/aaaa") -> 03/2026 | Q30: TELERISCO | R30: 1018345066 | S30: TRANSPORTADORA ANDARILHO LTDA | T30: 57904437000177 | U30: Optante pelo Simples Nacional desde 30/10/2024 | V30: 11311094
A31: =TEXT(B31,"mm/aaaa") -> 03/2026 | B31: 46086 | C31: SP | D31: 274 | E31: 1800000271 | F31: 2804.5 | H31: =ROUND(F31*1.5%,2) -> 42.07 | I31: =ROUND(F31*1%,2) -> 28.05 | J31: =ROUND(F31*3%,2) -> 84.14 | K31: =ROUND(F31*0.65%,2) -> 18.23 | L31: =SUM(I31:K31) -> 130.42 | M31: =F31-H31-I31-J31-K31 -> 2632.01 | N31: 1400000285 | O31: 46112 | P31: =TEXT(O31,"mm/aaaa") -> 03/2026 | Q31: TELERISCO | R31: 1017716043 | S31: ANSELMINI RODOVIARIO LTDA | T31: 57951895000167 | U31: NÃO optante pelo Simples Nacional | V31: 11311094
A32: =TEXT(B32,"mm/aaaa") -> 03/2026 | B32: 46086 | C32: SP | D32: 275 | E32: 1800000272 | F32: 3588 | H32: =ROUND(F32*1.5%,2) -> 53.82 | I32: =ROUND(F32*1%,2) -> 35.88 | J32: =ROUND(F32*3%,2) -> 107.64 | K32: =ROUND(F32*0.65%,2) -> 23.32 | L32: =SUM(I32:K32) -> 166.84 | M32: =F32-H32-I32-J32-K32 -> 3367.34 | N32: 1400000330 | O32: 46135 | P32: =TEXT(O32,"mm/aaaa") -> 04/2026 | Q32: TELERISCO | R32: 1018075263 | S32: TRILOG EXPRESS LTDA | T32: 58578490000198 | U32: NÃO optante pelo Simples Nacional | V32: 11311094
A33: =TEXT(B33,"mm/aaaa") -> 03/2026 | B33: 46086 | C33: SP | D33: 276 | E33: 1800000255 | F33: 97.5 | H33: 0 | I33: 0 | J33: 0 | K33: 0 | L33: =SUM(I33:K33) -> 0 | M33: =F33-H33-I33-J33-K33 -> 97.5 | N33: 1400000300 | O33: 46112 | P33: =TEXT(O33,"mm/aaaa") -> 03/2026 | Q33: TELERISCO | R33: 1018120652 | S33: ARK LOGISTICA ASSESSORIA E TREINAMENTOS EM COMEX LTDA | T33: 30341404000100 | U33: NÃO optante pelo Simples Nacional | V33: 11311094
A34: =TEXT(B34,"mm/aaaa") -> 03/2026 | B34: 46086 | C34: SP | D34: 277 | E34: 1800000285 | F34: 2907.5 | H34: =ROUND(F34*1.5%,2) -> 43.61 | I34: =ROUND(F34*1%,2) -> 29.08 | J34: =ROUND(F34*3%,2) -> 87.23 | K34: =ROUND(F34*0.65%,2) -> 18.9 | L34: =SUM(I34:K34) -> 135.21 | M34: =F34-H34-I34-J34-K34 -> 2728.68 | O34: EM ABERTO | Q34: TELERISCO | R34: 1014825740 | S34: PC LOGISTICA LTDA | T34: 44120318000181 | U34: NÃO optante pelo Simples Nacional | V34: 11311094
A35: =TEXT(B35,"mm/aaaa") -> 03/2026 | B35: 46086 | C35: SP | D35: 278 | E35: 1800000300 | F35: 250 | H35: 0 | I35: 0 | J35: 0 | K35: 0 | L35: =SUM(I35:K35) -> 0 | M35: =F35-H35-I35-J35-K35 -> 250 | N35: 1400000213 | O35: 46107 | P35: =TEXT(O35,"mm/aaaa") -> 03/2026 | Q35: TELERISCO | R35: 1005618488 | S35: CENTRAL LOGISTICA DE TRANSPORTE LTDA | T35: 8152302000197 | U35: NÃO optante pelo Simples Nacional | V35: 11311094
A36: =TEXT(B36,"mm/aaaa") -> 03/2026 | B36: 46086 | C36: SP | D36: 279 | E36: 1800000195 | F36: 250 | H36: 0 | I36: =ROUND(F36*1%,2) -> 2.5 | J36: =ROUND(F36*3%,2) -> 7.5 | K36: =ROUND(F36*0.65%,2) -> 1.63 | L36: =SUM(I36:K36) -> 11.63 | M36: =F36-H36-I36-J36-K36 -> 238.37 | N36: 1400000270 | O36: 46112 | P36: =TEXT(O36,"mm/aaaa") -> 03/2026 | Q36: TELERISCO | R36: 1002640697 | S36: COOP DE TRANSP AUTONOMOS DE BENS DE SALTO E REGIAO | T36: 5370882000109 | U36: NÃO optante pelo Simples Nacional | V36: 11311094
A37: =TEXT(B37,"mm/aaaa") -> 03/2026 | B37: 46086 | C37: SP | D37: 280 | E37: 1800000210 | F37: 15298 | H37: =ROUND(F37*1.5%,2) -> 229.47 | I37: =ROUND(F37*1%,2) -> 152.98 | J37: =ROUND(F37*3%,2) -> 458.94 | K37: =ROUND(F37*0.65%,2) -> 99.44 | L37: =SUM(I37:K37) -> 711.36 | M37: =F37-H37-I37-J37-K37 -> 14357.17 | N37: 1400000195 | O37: 46107 | P37: =TEXT(O37,"mm/aaaa") -> 03/2026 | Q37: TELERISCO | R37: 1001187614 | S37: INTEGRA BRASIL TRANSPORTES LTDA | T37: 9395767000131 | U37: NÃO optante pelo Simples Nacional | V37: 11311094
A38: =TEXT(B38,"mm/aaaa") -> 03/2026 | B38: 46086 | C38: SP | D38: 281 | E38: 1800000225 | F38: 345 | H38: 0 | I38: =ROUND(F38*1%,2) -> 3.45 | J38: =ROUND(F38*3%,2) -> 10.35 | K38: =ROUND(F38*0.65%,2) -> 2.24 | L38: =SUM(I38:K38) -> 16.04 | M38: =F38-H38-I38-J38-K38 -> 328.96 | N38: 1400000315 | O38: 46112 | P38: =TEXT(O38,"mm/aaaa") -> 03/2026 | Q38: TELERISCO | R38: 1007834227 | S38: ZANIN TRANSPORTES E LOGISTICA LTDA | T38: 14457026000178 | U38: NÃO optante pelo Simples Nacional | V38: 11311094
A39: =TEXT(B39,"mm/aaaa") -> 03/2026 | B39: 46086 | C39: SP | D39: 282 | E39: 1800000226 | F39: 5651 | H39: =ROUND(F39*1.5%,2) -> 84.77 | I39: =ROUND(F39*1%,2) -> 56.51 | J39: =ROUND(F39*3%,2) -> 169.53 | K39: =ROUND(F39*0.65%,2) -> 36.73 | L39: =SUM(I39:K39) -> 262.77 | M39: =F39-H39-I39-J39-K39 -> 5303.46 | N39: 1400000210 | O39: 46107 | P39: =TEXT(O39,"mm/aaaa") -> 03/2026 | Q39: TELERISCO | R39: 1008259405 | S39: SENSITIVE TRANSPORTES LTDA ME | T39: 28759933000186 | U39: NÃO optante pelo Simples Nacional | V39: 11311094
A40: =TEXT(B40,"mm/aaaa") -> 03/2026 | B40: 46086 | C40: SP | D40: 283 | E40: 1800000240 | F40: 966 | H40: =ROUND(F40*1.5%,2) -> 14.49 | I40: =ROUND(F40*1%,2) -> 9.66 | J40: =ROUND(F40*3%,2) -> 28.98 | K40: =ROUND(F40*0.65%,2) -> 6.28 | L40: =SUM(I40:K40) -> 44.92 | M40: =F40-H40-I40-J40-K40 -> 906.59 | N40: 1400000225 | O40: 46107 | P40: =TEXT(O40,"mm/aaaa") -> 03/2026 | Q40: TELERISCO | R40: 1018585294 | S40: NAIK TRANSPORTE E L LTDA | T40: 29260142000170 | U40: NÃO optante pelo Simples Nacional | V40: 11311094
A41: =TEXT(B41,"mm/aaaa") -> 03/2026 | B41: 46086 | C41: SP | D41: 284 | E41: 1800000256 | F41: 250 | H41: 0 | I41: 0 | J41: 0 | K41: 0 | L41: =SUM(I41:K41) -> 0 | M41: =F41-H41-I41-J41-K41 -> 250 | N41: 1400000180 | O41: 46107 | P41: =TEXT(O41,"mm/aaaa") -> 03/2026 | Q41: TELERISCO | R41: 1018840151 | S41: EAGLE GROUP TECHNOLOGIES LOGISTICS E TRANSPORTS LTDA | T41: 55365607000167 | U41: Optante pelo Simples Nacional desde 03/06/2024 | V41: 11311094
...

Sheet RECEBIMENTO
A1: Faturamento e Apuração dos Tributos - Notas Fiscais emitidas
A2: SOMPO SERVICES GESTAO DE RISCOS E VISTORIA LTDA | K2: 46.206.637/0001-30
A4: COMP EMISSÃO | B4: DATA EMISSÃO | C4: Prefeitura | D4: Nº NF | E4: Numero SAP | F4: Valor N. Fiscal | G4: ISS - 5% | H4: IRRF - 1,5% | I4: CSLL - 1% | J4: COFINS- 3% | K4: PIS- 0,65% | L4: TOTAL CSRF | M4: Valor | N4: DOC REC BANCO | O4: Dt. Dep. | P4: COMP RECEBIMENTO | Q4: Cód | R4: BP | S4: Razão | T4: CNPJ | U4: REGIME
A5: 05/2026 | B5: 46150 | C5: SP | D5: 341 | E5: 0 | F5: 0 | G5: 0 | H5: 0 | I5: 0 | J5: 0 | K5: 0 | L5: 0 | M5: CANCELADA | N5: 0 | O5: 0 | P5: 0 | Q5: NSTECH | R5: 0 | S5: 0 | T5: 0 | U5: N/A
A6: 05/2026 | B6: 46150 | C6: SP | D6: 342 | E6: 0 | F6: 0 | G6: 0 | H6: 0 | I6: 0 | J6: 0 | K6: 0 | L6: 0 | M6: CANCELADA | N6: 0 | O6: 0 | P6: 0 | Q6: NSTECH | R6: 0 | S6: 0 | T6: 0 | U6: N/A
A7: 05/2026 | B7: 46150 | C7: SP | D7: 343 | E7: 0 | F7: 0 | G7: 0 | H7: 0 | I7: 0 | J7: 0 | K7: 0 | L7: 0 | M7: CANCELADA | N7: 0 | O7: 0 | P7: 0 | Q7: NSTECH | R7: 0 | S7: 0 | T7: 0 | U7: N/A
A8: 05/2026 | B8: 46150 | C8: SP | D8: 344 | E8: 0 | F8: 0 | G8: 0 | H8: 0 | I8: 0 | J8: 0 | K8: 0 | L8: 0 | M8: CANCELADA | N8: 0 | O8: 0 | P8: 0 | Q8: NSTECH | R8: 0 | S8: 0 | T8: 0 | U8: N/A
A9: 05/2026 | B9: 46150 | C9: SP | D9: 346 | E9: 0 | F9: 0 | G9: 0 | H9: =ROUND(F9*1.5%,2) -> 0 | I9: =ROUND(F9*1%,2) -> 0 | J9: =ROUND(F9*3%,2) -> 0 | K9: =ROUND(F9*0.65%,2) -> 0 | L9: =SUM(I9:K9) -> 0 | M9: CANCELADA | N9: 0 | O9: 0 | P9: 0 | Q9: NSTECH | R9: 0 | S9: 0 | T9: 0 | U9: N/A
A10: 05/2026 | B10: 46170 | C10: SP | D10: 351 | E10: 0 | F10: 0 | G10: 0 | H10: 0 | I10: 0 | J10: 0 | K10: 0 | L10: 0 | M10: CANCELADA | N10: 0 | O10: 0 | P10: 0 | Q10: NSTECH | R10: 0 | S10: 0 | T10: 0 | U10: N/A
A11: 06/2026 | B11: 46182 | C11: SP | D11: 353 | E11: 0 | F11: 0 | G11: 0 | H11: 0 | I11: 0 | J11: 0 | K11: 0 | L11: 0 | M11: CANCELADA | N11: 0 | O11: 0 | P11: 0 | Q11: NSTECH | R11: 0 | S11: 0 | T11: 0 | U11: N/A
A12: 06/2026 | B12: 46182 | C12: SP | D12: 354 | E12: 0 | F12: 0 | G12: 0 | H12: 0 | I12: 0 | J12: 0 | K12: 0 | L12: 0 | M12: CANCELADA | N12: 0 | O12: 0 | P12: 0 | Q12: NSTECH | R12: 0 | S12: 0 | T12: 0 | U12: N/A
A13: 06/2026 | B13: 46182 | C13: SP | D13: 355 | E13: 0 | F13: 0 | G13: 0 | H13: 0 | I13: 0 | J13: 0 | K13: 0 | L13: 0 | M13: CANCELADA | N13: 0 | O13: 0 | P13: 0 | Q13: NSTECH | R13: 0 | S13: 0 | T13: 0 | U13: N/A
A14: 12/2025 | B14: 46020 | C14: SP | D14: 247 | F14: 8468 | G14: 0 | H14: =ROUND(F14*1.5%,2) -> 127.02 | I14: =ROUND(F14*1%,2) -> 84.68 | J14: =ROUND(F14*3%,2) -> 254.04 | K14: =ROUND(F14*0.65%,2) -> 55.04 | L14: =SUM(I14:K14) -> 393.76 | M14: =F14-H14-I14-J14-K14 -> 7947.22 | N14: 1400000000 | O14: 46035 | P14: =TEXT(O14,"mm/aaaa") -> 01/2026 | Q14: TELERISCO | R14: 1008259405 | S14: SENSITIVE TRANSPORTES LTDA ME | T14: 28759933000186 | U14: NÃO optante pelo Simples Nacional
A15: =TEXT(B15,"mm/aaaa") -> 01/2026 | B15: 46028 | C15: SP | D15: 248 | E15: 1800000015 | F15: 547.5 | G15: 0 | H15: 0 | I15: =ROUND(F15*1%,2) -> 5.48 | J15: =ROUND(F15*3%,2) -> 16.43 | K15: =ROUND(F15*0.65%,2) -> 3.56 | L15: =SUM(I15:K15) -> 25.47 | M15: =F15-H15-I15-J15-K15 -> 522.03 | N15: 1400000015 | O15: 46043 | P15: =TEXT(O15,"mm/aaaa") -> 01/2026 | Q15: TELERISCO | R15: 1002640697 | S15: COOP DE TRANSP AUTONOMOS DE BENS DE SALTO E REGIAO | T15: 5370882000109 | U15: NÃO optante pelo Simples Nacional
A16: =TEXT(B16,"mm/aaaa") -> 01/2026 | B16: 46028 | C16: SP | D16: 249 | E16: 1800000000 | F16: 20758.5 | G16: 0 | H16: =ROUND(F16*1.5%,2) -> 311.38 | I16: =ROUND(F16*1%,2) -> 207.59 | J16: =ROUND(F16*3%,2) -> 622.76 | K16: =ROUND(F16*0.65%,2) -> 134.93 | L16: =SUM(I16:K16) -> 965.28 | M16: =F16-H16-I16-J16-K16 -> 19481.84 | N16: 1400000030 | O16: 46043 | P16: =TEXT(O16,"mm/aaaa") -> 01/2026 | Q16: TELERISCO | R16: 1001187614 | S16: INTEGRA BRASIL TRANSPORTES LTDA | T16: 9395767000131 | U16: NÃO optante pelo Simples Nacional
A17: =TEXT(B17,"mm/aaaa") -> 01/2026 | B17: 46028 | C17: SP | D17: 250 | E17: 1800000045 | F17: 1242 | G17: 0 | H17: =ROUND(F17*1.5%,2) -> 18.63 | I17: =ROUND(F17*1%,2) -> 12.42 | J17: =ROUND(F17*3%,2) -> 37.26 | K17: =ROUND(F17*0.65%,2) -> 8.07 | L17: =SUM(I17:K17) -> 57.75 | M17: =F17-H17-I17-J17-K17 -> 1165.62 | N17: 1400000045 | O17: 46043 | P17: =TEXT(O17,"mm/aaaa") -> 01/2026 | Q17: TELERISCO | R17: 1014825740 | S17: PC LOGISTICA LTDA | T17: 44120318000181 | U17: NÃO optante pelo Simples Nacional
A18: =TEXT(B18,"mm/aaaa") -> 01/2026 | B18: 46028 | C18: SP | D18: 251 | E18: 1800000016 | F18: 11366 | G18: 0 | H18: =ROUND(F18*1.5%,2) -> 170.49 | I18: =ROUND(F18*1%,2) -> 113.66 | J18: =ROUND(F18*3%,2) -> 340.98 | K18: =ROUND(F18*0.65%,2) -> 73.88 | L18: =SUM(I18:K18) -> 528.52 | M18: =F18-H18-I18-J18-K18 -> 10666.99 | N18: 1400000016 | O18: 46043 | P18: =TEXT(O18,"mm/aaaa") -> 01/2026 | Q18: TELERISCO | R18: 1008259405 | S18: SENSITIVE TRANSPORTES LTDA ME | T18: 28759933000186 | U18: NÃO optante pelo Simples Nacional
A19: =TEXT(B19,"mm/aaaa") -> 01/2026 | B19: 46028 | C19: SP | D19: 252 | E19: 1800000030 | F19: 3233.5 | G19: 0 | H19: =ROUND(F19*1.5%,2) -> 48.5 | I19: =ROUND(F19*1%,2) -> 32.34 | J19: =ROUND(F19*3%,2) -> 97.01 | K19: =ROUND(F19*0.65%,2) -> 21.02 | L19: =SUM(I19:K19) -> 150.37 | M19: =F19-H19-I19-J19-K19 -> 3034.63 | N19: 1400000060 | O19: 46043 | P19: =TEXT(O19,"mm/aaaa") -> 01/2026 | Q19: TELERISCO | R19: 1007834227 | S19: ZANIN TRANSPORTES E LOGISTICA LTDA | T19: 14457026000178 | U19: NÃO optante pelo Simples Nacional
A20: 12/2025 | B20: 46013 | C20: SP | D20: 242 | E20: 2200001471 | F20: 5500.06 | H20: =ROUND(F20*1.5%,2) -> 82.5 | I20: =ROUND(F20*1%,2) -> 55 | J20: =ROUND(F20*3%,2) -> 165 | K20: =ROUND(F20*0.65%,2) -> 35.75 | L20: =SUM(I20:K20) -> 255.75 | M20: =F20-H20-I20-J20-K20 -> 5161.81 | N20: 1400000090 | O20: 46055 | P20: =TEXT(O20,"mm/aaaa") -> 02/2026 | Q20: 3115 | R20: 1007620183 | S20: GOLDEN SAT | T20: 9446817000162 | U20: NÃO optante pelo Simples Nacional
A21: 10/2025 | B21: 45957 | C21: SP | D21: 227 | E21: 1800000210 | F21: 14128.31 | H21: =ROUND(F21*1.5%,2) -> 211.92 | I21: =ROUND(F21*1%,2) -> 141.28 | J21: =ROUND(F21*3%,2) -> 423.85 | K21: =ROUND(F21*0.65%,2) -> 91.83 | L21: =SUM(I21:K21) -> 656.96 | M21: =F21-H21-I21-J21-K21 -> 13259.43 | N21: 1400000075 | O21: 46055 | P21: =TEXT(O21,"mm/aaaa") -> 02/2026 | Q21: 3115 | R21: 1007620183 | S21: GOLDEN SAT | T21: 9446817000162 | U21: NÃO optante pelo Simples Nacional
A22: =TEXT(B22,"mm/aaaa") -> 02/2026 | B22: 46061 | C22: SP | D22: 258 | E22: 1800000090 | F22: 16005.5 | H22: =ROUND(F22*1.5%,2) -> 240.08 | I22: =ROUND(F22*1%,2) -> 160.06 | J22: =ROUND(F22*3%,2) -> 480.17 | K22: =ROUND(F22*0.65%,2) -> 104.04 | L22: =SUM(I22:K22) -> 744.27 | M22: =F22-H22-I22-J22-K22 -> 15021.15 | N22: 1400000105 | O22: 46079 | P22: =TEXT(O22,"mm/aaaa") -> 02/2026 | Q22: TELERISCO | R22: 1001187614 | S22: INTEGRA BRASIL TRANSPORTES LTDA | T22: 9395767000131 | U22: NÃO optante pelo Simples Nacional
A23: =TEXT(B23,"mm/aaaa") -> 02/2026 | B23: 46062 | C23: SP | D23: 259 | E23: 1800000151 | F23: 69 | H23: 0 | I23: 0 | J23: 0 | K23: 0 | L23: =SUM(I23:K23) -> 0 | M23: =F23-H23-I23-J23-K23 -> 69 | N23: 1400000150 | O23: 46079 | P23: =TEXT(O23,"mm/aaaa") -> 02/2026 | Q23: TELERISCO | R23: 1018345066 | S23: TRANSPORTADORA ANDARILHO LTDA | T23: 57904437000177 | U23: Optante pelo Simples Nacional desde 30/10/2024
A24: =TEXT(B24,"mm/aaaa") -> 02/2026 | B24: 46062 | C24: SP | D24: 260 | E24: 1800000105 | F24: 3540.5 | H24: =ROUND(F24*1.5%,2) -> 53.11 | I24: =ROUND(F24*1%,2) -> 35.41 | J24: =ROUND(F24*3%,2) -> 106.22 | K24: =ROUND(F24*0.65%,2) -> 23.01 | L24: =SUM(I24:K24) -> 164.64 | M24: =F24-H24-I24-J24-K24 -> 3322.75 | N24: 1400000120 | O24: 46079 | P24: =TEXT(O24,"mm/aaaa") -> 02/2026 | Q24: TELERISCO | R24: 1008259405 | S24: SENSITIVE TRANSPORTES LTDA ME | T24: 28759933000186 | U24: NÃO optante pelo Simples Nacional
A25: =TEXT(B25,"mm/aaaa") -> 02/2026 | B25: 46062 | C25: SP | D25: 263 | E25: 1800000135 | F25: 250 | H25: 0 | I25: =ROUND(F25*1%,2) -> 2.5 | J25: =ROUND(F25*3%,2) -> 7.5 | K25: =ROUND(F25*0.65%,2) -> 1.63 | L25: =SUM(I25:K25) -> 11.63 | M25: =F25-H25-I25-J25-K25 -> 238.37 | N25: 1400000135 | O25: 46079 | P25: =TEXT(O25,"mm/aaaa") -> 02/2026 | Q25: TELERISCO | R25: 1002640697 | S25: COOP DE TRANSP AUTONOMOS DE BENS DE SALTO E REGIAO | T25: 5370882000109 | U25: NÃO optante pelo Simples Nacional
A26: =TEXT(B26,"mm/aaaa") -> 02/2026 | B26: 46062 | C26: SP | D26: 264 | E26: 1800000122 | F26: 571 | H26: 0 | I26: =ROUND(F26*1%,2) -> 5.71 | J26: =ROUND(F26*3%,2) -> 17.13 | K26: =ROUND(F26*0.65%,2) -> 3.71 | L26: =SUM(I26:K26) -> 26.55 | M26: =F26-H26-I26-J26-K26 -> 544.45 | N26: 1400000165 | O26: 46080 | P26: =TEXT(O26,"mm/aaaa") -> 02/2026 | Q26: TELERISCO | R26: 1017716043 | S26: ANSELMINI RODOVIARIO LTDA | T26: 57951895000167 | U26: NÃO optante pelo Simples Nacional
A27: =TEXT(B27,"mm/aaaa") -> 02/2026 | B27: 46062 | C27: SP | D27: 265 | E27: 1800000150 | F27: 1458.5 | H27: =ROUND(F27*1.5%,2) -> 21.88 | I27: =ROUND(F27*1%,2) -> 14.59 | J27: =ROUND(F27*3%,2) -> 43.76 | K27: =ROUND(F27*0.65%,2) -> 9.48 | L27: =SUM(I27:K27) -> 67.83 | M27: =F27-H27-I27-J27-K27 -> 1368.79 | N27: 1400000136 | O27: 46079 | P27: =TEXT(O27,"mm/aaaa") -> 02/2026 | Q27: TELERISCO | R27: 1007834227 | S27: ZANIN TRANSPORTES E LOGISTICA LTDA | T27: 14457026000178 | U27: NÃO optante pelo Simples Nacional
A28: =TEXT(B28,"mm/aaaa") -> 02/2026 | B28: 46062 | C28: SP | D28: 266 | E28: 1800000123 | F28: 235.5 | H28: 0 | I28: =ROUND(F28*1%,2) -> 2.36 | J28: =ROUND(F28*3%,2) -> 7.07 | K28: =ROUND(F28*0.65%,2) -> 1.53 | L28: =SUM(I28:K28) -> 10.96 | M28: =F28-H28-I28-J28-K28 -> 224.54 | N28: 1400000166 | O28: 46080 | P28: =TEXT(O28,"mm/aaaa") -> 02/2026 | Q28: TELERISCO | R28: 1018930052 | S28: HE TRANSPORTES LTDA | T28: 45916594000113 | U28: NÃO optante pelo Simples Nacional
A29: =TEXT(B29,"mm/aaaa") -> 02/2026 | B29: 46062 | C29: SP | D29: 267 | E29: 1800000152 | F29: 78.5 | H29: 0 | I29: 0 | J29: 0 | K29: 0 | L29: =SUM(I29:K29) -> 0 | M29: =F29-H29-I29-J29-K29 -> 78.5 | N29: 1400000255 | O29: 46112 | P29: =TEXT(O29,"mm/aaaa") -> 03/2026 | Q29: TELERISCO | R29: 1017130541 | S29: TRANSPACKLOG TRANSPORTE DE CARGAS LTDA | T29: 53045500000106 | U29: Optante pelo Simples Nacional desde 01/01/2024
A30: =TEXT(B30,"mm/aaaa") -> 03/2026 | B30: 46086 | C30: SP | D30: 270 | E30: 1800000241 | F30: 138 | H30: 0 | I30: 0 | J30: 0 | K30: 0 | L30: =SUM(I30:K30) -> 0 | M30: =F30-H30-I30-J30-K30 -> 138 | N30: 1400000211 | O30: 46107 | P30: =TEXT(O30,"mm/aaaa") -> 03/2026 | Q30: TELERISCO | R30: 1018645192 | S30: SUNO DISTRIBUIDORA SOLAR LTDA | T30: 32764816000188 | U30: NÃO optante pelo Simples Nacional
A31: =TEXT(B31,"mm/aaaa") -> 03/2026 | B31: 46086 | C31: SP | D31: 272 | E31: 1800000257 | F31: 250 | H31: 0 | I31: 0 | J31: 0 | K31: 0 | L31: =SUM(I31:K31) -> 0 | M31: =F31-H31-I31-J31-K31 -> 250 | N31: 1400000181 | O31: 46107 | P31: =TEXT(O31,"mm/aaaa") -> 03/2026 | Q31: TELERISCO | R31: 1017130541 | S31: TRANSPACKLOG TRANSPORTE DE CARGAS LTDA | T31: 53045500000106 | U31: Optante pelo Simples Nacional desde 01/01/2024
A32: =TEXT(B32,"mm/aaaa") -> 03/2026 | B32: 46086 | C32: SP | D32: 273 | E32: 1800000286 | F32: 250 | H32: 0 | I32: 0 | J32: 0 | K32: 0 | L32: =SUM(I32:K32) -> 0 | M32: =F32-H32-I32-J32-K32 -> 250 | N32: 1400000240 | O32: 46107 | P32: =TEXT(O32,"mm/aaaa") -> 03/2026 | Q32: TELERISCO | R32: 1018345066 | S32: TRANSPORTADORA ANDARILHO LTDA | T32: 57904437000177 | U32: Optante pelo Simples Nacional desde 30/10/2024
A33: =TEXT(B33,"mm/aaaa") -> 03/2026 | B33: 46086 | C33: SP | D33: 274 | E33: 1800000271 | F33: 2804.5 | H33: =ROUND(F33*1.5%,2) -> 42.07 | I33: =ROUND(F33*1%,2) -> 28.05 | J33: =ROUND(F33*3%,2) -> 84.14 | K33: =ROUND(F33*0.65%,2) -> 18.23 | L33: =SUM(I33:K33) -> 130.42 | M33: =F33-H33-I33-J33-K33 -> 2632.01 | N33: 1400000285 | O33: 46112 | P33: =TEXT(O33,"mm/aaaa") -> 03/2026 | Q33: TELERISCO | R33: 1017716043 | S33: ANSELMINI RODOVIARIO LTDA | T33: 57951895000167 | U33: NÃO optante pelo Simples Nacional
A34: =TEXT(B34,"mm/aaaa") -> 03/2026 | B34: 46086 | C34: SP | D34: 276 | E34: 1800000255 | F34: 97.5 | H34: 0 | I34: 0 | J34: 0 | K34: 0 | L34: =SUM(I34:K34) -> 0 | M34: =F34-H34-I34-J34-K34 -> 97.5 | N34: 1400000300 | O34: 46112 | P34: =TEXT(O34,"mm/aaaa") -> 03/2026 | Q34: TELERISCO | R34: 1018120652 | S34: ARK LOGISTICA ASSESSORIA E TREINAMENTOS EM COMEX LTDA | T34: 30341404000100 | U34: NÃO optante pelo Simples Nacional
A35: =TEXT(B35,"mm/aaaa") -> 03/2026 | B35: 46086 | C35: SP | D35: 278 | E35: 1800000300 | F35: 250 | H35: 0 | I35: 0 | J35: 0 | K35: 0 | L35: =SUM(I35:K35) -> 0 | M35: =F35-H35-I35-J35-K35 -> 250 | N35: 1400000213 | O35: 46107 | P35: =TEXT(O35,"mm/aaaa") -> 03/2026 | Q35: TELERISCO | R35: 1005618488 | S35: CENTRAL LOGISTICA DE TRANSPORTE LTDA | T35: 8152302000197 | U35: NÃO optante pelo Simples Nacional
A36: =TEXT(B36,"mm/aaaa") -> 03/2026 | B36: 46086 | C36: SP | D36: 279 | E36: 1800000195 | F36: 250 | H36: 0 | I36: =ROUND(F36*1%,2) -> 2.5 | J36: =ROUND(F36*3%,2) -> 7.5 | K36: =ROUND(F36*0.65%,2) -> 1.63 | L36: =SUM(I36:K36) -> 11.63 | M36: =F36-H36-I36-J36-K36 -> 238.37 | N36: 1400000270 | O36: 46112 | P36: =TEXT(O36,"mm/aaaa") -> 03/2026 | Q36: TELERISCO | R36: 1002640697 | S36: COOP DE TRANSP AUTONOMOS DE BENS DE SALTO E REGIAO | T36: 5370882000109 | U36: NÃO optante pelo Simples Nacional
A37: =TEXT(B37,"mm/aaaa") -> 03/2026 | B37: 46086 | C37: SP | D37: 280 | E37: 1800000210 | F37: 15298 | H37: =ROUND(F37*1.5%,2) -> 229.47 | I37: =ROUND(F37*1%,2) -> 152.98 | J37: =ROUND(F37*3%,2) -> 458.94 | K37: =ROUND(F37*0.65%,2) -> 99.44 | L37: =SUM(I37:K37) -> 711.36 | M37: =F37-H37-I37-J37-K37 -> 14357.17 | N37: 1400000195 | O37: 46107 | P37: =TEXT(O37,"mm/aaaa") -> 03/2026 | Q37: TELERISCO | R37: 1001187614 | S37: INTEGRA BRASIL TRANSPORTES LTDA | T37: 9395767000131 | U37: NÃO optante pelo Simples Nacional
A38: =TEXT(B38,"mm/aaaa") -> 03/2026 | B38: 46086 | C38: SP | D38: 281 | E38: 1800000225 | F38: 345 | H38: 0 | I38: =ROUND(F38*1%,2) -> 3.45 | J38: =ROUND(F38*3%,2) -> 10.35 | K38: =ROUND(F38*0.65%,2) -> 2.24 | L38: =SUM(I38:K38) -> 16.04 | M38: =F38-H38-I38-J38-K38 -> 328.96 | N38: 1400000315 | O38: 46112 | P38: =TEXT(O38,"mm/aaaa") -> 03/2026 | Q38: TELERISCO | R38: 1007834227 | S38: ZANIN TRANSPORTES E LOGISTICA LTDA | T38: 14457026000178 | U38: NÃO optante pelo Simples Nacional
A39: =TEXT(B39,"mm/aaaa") -> 03/2026 | B39: 46086 | C39: SP | D39: 282 | E39: 1800000226 | F39: 5651 | H39: =ROUND(F39*1.5%,2) -> 84.77 | I39: =ROUND(F39*1%,2) -> 56.51 | J39: =ROUND(F39*3%,2) -> 169.53 | K39: =ROUND(F39*0.65%,2) -> 36.73 | L39: =SUM(I39:K39) -> 262.77 | M39: =F39-H39-I39-J39-K39 -> 5303.46 | N39: 1400000210 | O39: 46107 | P39: =TEXT(O39,"mm/aaaa") -> 03/2026 | Q39: TELERISCO | R39: 1008259405 | S39: SENSITIVE TRANSPORTES LTDA ME | T39: 28759933000186 | U39: NÃO optante pelo Simples Nacional
A40: =TEXT(B40,"mm/aaaa") -> 03/2026 | B40: 46086 | C40: SP | D40: 283 | E40: 1800000240 | F40: 966 | H40: =ROUND(F40*1.5%,2) -> 14.49 | I40: =ROUND(F40*1%,2) -> 9.66 | J40: =ROUND(F40*3%,2) -> 28.98 | K40: =ROUND(F40*0.65%,2) -> 6.28 | L40: =SUM(I40:K40) -> 44.92 | M40: =F40-H40-I40-J40-K40 -> 906.59 | N40: 1400000225 | O40: 46107 | P40: =TEXT(O40,"mm/aaaa") -> 03/2026 | Q40: TELERISCO | R40: 1018585294 | S40: NAIK TRANSPORTE E L LTDA | T40: 29260142000170 | U40: NÃO optante pelo Simples Nacional
A41: =TEXT(B41,"mm/aaaa") -> 03/2026 | B41: 46086 | C41: SP | D41: 284 | E41: 1800000256 | F41: 250 | H41: 0 | I41: 0 | J41: 0 | K41: 0 | L41: =SUM(I41:K41) -> 0 | M41: =F41-H41-I41-J41-K41 -> 250 | N41: 1400000180 | O41: 46107 | P41: =TEXT(O41,"mm/aaaa") -> 03/2026 | Q41: TELERISCO | R41: 1018840151 | S41: EAGLE GROUP TECHNOLOGIES LOGISTICS E TRANSPORTS LTDA | T41: 55365607000167 | U41: Optante pelo Simples Nacional desde 03/06/2024
...

Sheet Conciliação
B1: IRRF A COMPENSAR | F1: PIS A COMPENSAR | J1: COFINS A COMPENSAR | N1: CSLL A COMPENSAR | U1: 3 | V1: 4 | W1: 5 | X1: 6 | Y1: 7 | Z1: 8
B2: 11641009 | F2: 11644004 | J2: 11644005 | N2: 11642005 | S2: Table
A3: COMP | C3: Controle | D3: Dif | F3: Balancete | G3: Controle | H3: Dif | J3: Balancete | K3: Controle | L3: Dif | N3: Balancete | O3: Controle | P3: Dif | T3: Exercício/período | U3: 001.2026 | V3: 002.2026 | W3: 003.2026 | X3: 004.2026 | Y3: 005.2026 | Z3: 006.2026
A4: 46023 | B4: =VLOOKUP(B2,S2:AF10,3,0) -> 676.02 | C4: =SUMIF(RECEBIMENTO!$P$5:$P$202,Conciliação!A4,RECEBIMENTO!$H$5:$H$202) -> 676.02 | D4: =B4-C4 -> 0 | F4: =VLOOKUP(F2,$S$3:$AA$10,3,0) -> 362.69 | G4: =SUMIF(RECEBIMENTO!$P$5:$P$202,$A$4,RECEBIMENTO!$K$5:$K$202) -> 296.5 | H4: =F4-G4 -> 66.19 | J4: =VLOOKUP(J2,$S$3:$AA$10,3,0) -> 1775.79 | K4: =SUMIF(RECEBIMENTO!$P$5:$P$202,$A$4,RECEBIMENTO!$J$5:$J$202) -> 1368.48 | L4: =J4-K4 -> 407.31 | N4: =VLOOKUP(N2,$S$3:$AA$10,3,0) -> 456.17 | O4: =SUMIF(RECEBIMENTO!$P$5:$P$202,$A$4,RECEBIMENTO!$I$5:$I$202) -> 456.17 | P4: =N4-O4 -> 0 | S4: Conta do Razão | U4: Débitos | V4: Débitos | W4: Débitos | X4: Débitos | Y4: Débitos | Z4: Débitos
A5: 46054 | B5: =VLOOKUP($B$2,$S$2:$AF$11,4,0) -> 33142.17 | C5: =SUMIF(RECEBIMENTO!$P$5:$P$202,Conciliação!A5,RECEBIMENTO!$H$5:$H$202) -> 609.49 | D5: =B5-C5 -> 32532.68 | F5: =VLOOKUP($F$2,$S$2:$X$11,4,0) -> 270.98 | G5: =SUMIF(RECEBIMENTO!$P$5:$P$202,Conciliação!$A$5,RECEBIMENTO!$K$5:$K$202) -> 270.98 | H5: =F5-G5 -> 0 | J5: =VLOOKUP($J$2,$S$2:$X$11,4,0) -> 1250.7 | K5: =SUMIF(RECEBIMENTO!$P$5:$P$202,Conciliação!$A$5,RECEBIMENTO!$J$5:$J$202) -> 1250.7 | L5: =J5-K5 -> 0 | N5: =VLOOKUP($N$2,$S$2:$X$11,4,0) -> 11762.82 | O5: =SUMIF(RECEBIMENTO!$P$5:$P$202,Conciliação!$A$5,RECEBIMENTO!$I$5:$I$202) -> 416.91 | P5: =N5-O5 -> 11345.91 | S5: 11311011 | T5: SOMPO SEG REC RECEIT | U5: 7990.17 | V5: 23534.95 | W5: 4605.8 | X5: 2559.73 | Y5: 23127.07 | Z5: 17447.3
A6: 46082 | B6: =VLOOKUP($B$2,$S$2:$AF$11,5,0) -> 370.8 | C6: =SUMIF(RECEBIMENTO!$P$5:$P$202,Conciliação!A6,RECEBIMENTO!$H$5:$H$202) -> 370.8 | D6: =B6-C6 -> 0 | F6: =VLOOKUP($F$2,$S$2:$X$11,5,0) -> 166.18 | G6: =SUMIF(RECEBIMENTO!$P$5:$P$202,Conciliação!$A$6,RECEBIMENTO!$K$5:$K$202) -> 166.18 | H6: =F6-G6 -> 0 | J6: =VLOOKUP($J$2,$S$2:$X$11,5,0) -> 766.94 | K6: =SUMIF(RECEBIMENTO!$P$5:$P$202,Conciliação!$A$6,RECEBIMENTO!$J$5:$J$202) -> 766.94 | L6: =J6-K6 -> 0 | N6: =VLOOKUP($N$2,$S$2:$X$11,5,0) -> 255.65 | O6: =SUMIF(RECEBIMENTO!$P$5:$P$202,Conciliação!$A$6,RECEBIMENTO!$I$5:$I$202) -> 255.65 | P6: =N6-O6 -> 0 | S6: 11311094 | T6: Clientes SompoRisk | U6: 40381 | V6: 41289.5 | W6: 33783 | X6: 54959.5 | Y6: 64549.5 | Z6: 79288
A7: 46113 | B7: =VLOOKUP($B$2,$S$2:$AF$11,6,0) -> 626.91 | C7: =SUMIF(RECEBIMENTO!$P$5:$P$202,Conciliação!A7,RECEBIMENTO!$H$5:$H$202) -> 676.59 | D7: =B7-C7 -> -49.68 | F7: =VLOOKUP($F$2,$S$2:$AF$11,6,0) -> 947.28 | G7: =SUMIF(RECEBIMENTO!$P$5:$P$202,Conciliação!$A$7,RECEBIMENTO!$K$5:$K$202) -> 301.34 | H7: =F7-G7 -> 645.94 | J7: =VLOOKUP($J$2,$S$2:$X$11,6,0) -> 4365.8 | K7: =SUMIF(RECEBIMENTO!$P$5:$P$202,Conciliação!$A$7,RECEBIMENTO!$J$5:$J$202) -> 1390.7 | L7: =J7-K7 -> 2975.1 | N7: =VLOOKUP($N$2,$S$2:$X$11,6,0) -> 427.96 | O7: =SUMIF(RECEBIMENTO!$P$5:$P$202,Conciliação!$A$7,RECEBIMENTO!$I$5:$I$202) -> 463.58 | P7: =N7-O7 -> -35.62 | S7: 11642005 | T7: CSLL RETIDO A COMP | U7: 456.17 | V7: 11762.82 | W7: 255.65 | X7: 427.96 | Y7: 919.21 | Z7: 871.14
A8: 46143 | B8: =VLOOKUP($B$2,$S$2:$AF$11,7,0) -> 1359.99 | C8: =SUMIF(RECEBIMENTO!$P$5:$P$202,Conciliação!A8,RECEBIMENTO!$H$5:$H$202) -> 1359.99 | D8: =B8-C8 -> 0 | F8: =VLOOKUP($F$2,$S$2:$AF$11,7,0) -> 597.48 | G8: =SUMIF(RECEBIMENTO!$P$5:$P$202,Conciliação!A8,RECEBIMENTO!$K$5:$K$202) -> 597.48 | H8: =F8-G8 -> 0 | J8: =VLOOKUP($J$2,$S$2:$AF$11,7,0) -> 2757.5 | K8: =SUMIF(RECEBIMENTO!$P$5:$P$202,Conciliação!A8,RECEBIMENTO!$J$5:$J$202) -> 2757.5 | L8: =J8-K8 -> 0 | N8: =VLOOKUP($N$2,$S$2:$AF$11,7,0) -> 919.21 | O8: =SUMIF(RECEBIMENTO!$P$5:$P$202,Conciliação!A8,RECEBIMENTO!$I$5:$I$202) -> 919.21 | P8: =N8-O8 -> 0 | S8: 11644005 | T8: COFINS RETIDO A COMP | U8: 1775.79 | V8: 1250.7 | W8: 766.94 | X8: 4365.8 | Y8: 2757.5 | Z8: 2613.33
A9: 46174 | B9: =VLOOKUP($B$2,$S$2:$AF$11,8,0) -> 1225.76 | C9: =SUMIF(RECEBIMENTO!$P$5:$P$202,Conciliação!A9,RECEBIMENTO!$H$5:$H$202) -> 1225.76 | D9: =B9-C9 -> 0 | F9: =VLOOKUP($F$2,$S$2:$AF$11,8,0) -> 566.26 | G9: =SUMIF(RECEBIMENTO!$P$5:$P$202,Conciliação!A9,RECEBIMENTO!$K$5:$K$202) -> 566.26 | H9: =F9-G9 -> 0 | J9: =VLOOKUP($J$2,$S$2:$AF$11,8,0) -> 2613.33 | K9: =SUMIF(RECEBIMENTO!$P$5:$P$202,Conciliação!A9,RECEBIMENTO!$J$5:$J$202) -> 2613.33 | L9: =J9-K9 -> 0 | N9: =VLOOKUP($N$2,$S$2:$AF$11,8,0) -> 871.14 | O9: =SUMIF(RECEBIMENTO!$P$5:$P$202,Conciliação!A9,RECEBIMENTO!$I$5:$I$202) -> 871.14 | P9: =N9-O9 -> 0 | S9: 11644004 | T9: PIS RETIDO A COMP | U9: 362.69 | V9: 270.98 | W9: 166.18 | X9: 947.28 | Y9: 597.48 | Z9: 566.26
A10: 46204 | B10: =VLOOKUP($B$2,$S$2:$AF$11,9,0) -> 0 | C10: =SUMIF(RECEBIMENTO!$P$5:$P$202,Conciliação!A10,RECEBIMENTO!$H$5:$H$202) -> 0 | D10: =B10-C10 -> 0 | F10: =VLOOKUP($F$2,$S$2:$AF$11,9,0) -> 0 | G10: =SUMIF(RECEBIMENTO!$P$5:$P$202,Conciliação!A10,RECEBIMENTO!$K$5:$K$202) -> 0 | H10: =F10-G10 -> 0 | K10: =SUMIF(RECEBIMENTO!$P$5:$P$202,Conciliação!A10,RECEBIMENTO!$J$5:$J$202) -> 0 | L10: =J10-K10 -> 0 | O10: =SUMIF(RECEBIMENTO!$P$5:$P$202,Conciliação!A10,RECEBIMENTO!$I$5:$I$202) -> 0 | P10: =N10-O10 -> 0 | S10: 11641009 | T10: IR RETIDO SERV PREST | U10: 676.02 | V10: 33142.17 | W10: 370.8 | X10: 626.91 | Y10: 1359.99 | Z10: 1225.76
A11: 46235 | B11: =VLOOKUP($B$2,$S$2:$AF$11,10,0) -> 0 | C11: =SUMIF(RECEBIMENTO!$P$5:$P$202,Conciliação!A11,RECEBIMENTO!$H$5:$H$202) -> 0 | D11: =B11-C11 -> 0 | F11: =VLOOKUP($F$2,$S$2:$AF$11,10,0) -> 0 | G11: =SUMIF(RECEBIMENTO!$P$5:$P$202,Conciliação!A11,RECEBIMENTO!$K$5:$K$202) -> 0 | H11: =F11-G11 -> 0 | K11: =SUMIF(RECEBIMENTO!$P$5:$P$202,Conciliação!A11,RECEBIMENTO!$J$5:$J$202) -> 0 | L11: =J11-K11 -> 0 | O11: =SUMIF(RECEBIMENTO!$P$5:$P$202,Conciliação!A11,RECEBIMENTO!$I$5:$I$202) -> 0 | P11: =N11-O11 -> 0
A12: 46266 | B12: =VLOOKUP($B$2,$S$2:$AF$11,11,0) -> 0 | C12: =SUMIF(RECEBIMENTO!$P$5:$P$202,Conciliação!A12,RECEBIMENTO!$H$5:$H$202) -> 0 | D12: =B12-C12 -> 0 | F12: =VLOOKUP($F$2,$S$2:$AF$11,11,0) -> 0 | G12: =SUMIF(RECEBIMENTO!$P$5:$P$202,Conciliação!A12,RECEBIMENTO!$K$5:$K$202) -> 0 | H12: =F12-G12 -> 0 | K12: =SUMIF(RECEBIMENTO!$P$5:$P$202,Conciliação!A12,RECEBIMENTO!$J$5:$J$202) -> 0 | L12: =J12-K12 -> 0 | O12: =SUMIF(RECEBIMENTO!$P$5:$P$202,Conciliação!A12,RECEBIMENTO!$I$5:$I$202) -> 0 | P12: =N12-O12 -> 0
A13: 46296 | B13: =VLOOKUP($B$2,$S$2:$AF$11,12,0) -> 0 | C13: =SUMIF(RECEBIMENTO!$P$5:$P$202,Conciliação!A13,RECEBIMENTO!$H$5:$H$202) -> 0 | D13: =B13-C13 -> 0 | F13: =VLOOKUP($F$2,$S$2:$AF$11,12,0) -> 0 | G13: =SUMIF(RECEBIMENTO!$P$5:$P$202,Conciliação!A13,RECEBIMENTO!$K$5:$K$202) -> 0 | H13: =F13-G13 -> 0 | K13: =SUMIF(RECEBIMENTO!$P$5:$P$202,Conciliação!A13,RECEBIMENTO!$J$5:$J$202) -> 0 | L13: =J13-K13 -> 0 | O13: =SUMIF(RECEBIMENTO!$P$5:$P$202,Conciliação!A13,RECEBIMENTO!$I$5:$I$202) -> 0 | P13: =N13-O13 -> 0
A14: 46327 | B14: =VLOOKUP($B$2,$S$2:$AF$11,13,0) -> 0 | C14: =SUMIF(RECEBIMENTO!$P$5:$P$202,Conciliação!A14,RECEBIMENTO!$H$5:$H$202) -> 0 | D14: =B14-C14 -> 0 | F14: =VLOOKUP($F$2,$S$2:$AF$11,13,0) -> 0 | G14: =SUMIF(RECEBIMENTO!$P$5:$P$202,Conciliação!A14,RECEBIMENTO!$K$5:$K$202) -> 0 | H14: =F14-G14 -> 0 | K14: =SUMIF(RECEBIMENTO!$P$5:$P$202,Conciliação!A14,RECEBIMENTO!$J$5:$J$202) -> 0 | L14: =J14-K14 -> 0 | O14: =SUMIF(RECEBIMENTO!$P$5:$P$202,Conciliação!A14,RECEBIMENTO!$I$5:$I$202) -> 0 | P14: =N14-O14 -> 0
A15: 46357 | B15: =VLOOKUP($B$2,$S$2:$AF$11,14,0) -> 0 | C15: =SUMIF(RECEBIMENTO!$P$5:$P$202,Conciliação!A15,RECEBIMENTO!$H$5:$H$202) -> 0 | D15: =B15-C15 -> 0 | F15: =VLOOKUP($F$2,$S$2:$AF$11,14,0) -> 0 | G15: =SUMIF(RECEBIMENTO!$P$5:$P$202,Conciliação!A15,RECEBIMENTO!$K$5:$K$202) -> 0 | H15: =F15-G15 -> 0 | K15: =SUMIF(RECEBIMENTO!$P$5:$P$202,Conciliação!A15,RECEBIMENTO!$J$5:$J$202) -> 0 | L15: =J15-K15 -> 0 | O15: =SUMIF(RECEBIMENTO!$P$5:$P$202,Conciliação!A15,RECEBIMENTO!$I$5:$I$202) -> 0 | P15: =N15-O15 -> 0
C16: =SUM(C4:C15) -> 4918.65 | G16: =SUM(G4:G15) -> 2198.74 | K16: =SUM(K4:K15) -> 10147.65 | O16: =SUM(O4:O15) -> 3382.66
